Workbook

Sheet PRODUCT LIST
A1: S.NO. | B1: IMAGE | C1: PRODUCT CODE | D1: DESCRIPTION | E1: SIZE IN CM | F1: SIZE IN INCH | G1: PACKING SIZE | H1: CBM | I1: PRICE ($) | J1: PARAMETRIC RATE ($) | K1: AS DISCUSSED RATE ($) | L1: WAGES | M1: LOADABILITY FOR 40FT
A2: 1 | C2: DF20001 | D2: MANGO WOOD 4 DOOR SIDEBOARD | E2: 155X45X85 | F2: 61X18X33 | G2: 160X50X90 | H2: ='DF20001'!E27 -> 0.72 | I2: =INDEX('DF20001'!H:H,MATCH("TOTAL COSTING",'DF20001'!A:A,0)) -> 181.51552 | J2: =INDEX('DF20001'!H:H,MATCH("PARAMETRIC COSTING",'DF20001'!A:A,0)) -> 158.166 | K2: 240 | L2: 1100 | M2: =65/H2 -> 90.277778
A3: 2 | C3: DF20002 | D3: ACACIA 6 DRAWER CHEST | E3: 110X45X80 | F3: 43X18X31 | G3: 115X50X85 | H3: ='DF20002'!E27 -> 0.48875 | I3: =INDEX('DF20002'!H:H,MATCH("TOTAL COSTING",'DF20002'!A:A,0)) -> 130.58192 | J3: =INDEX('DF20002'!H:H,MATCH("PARAMETRIC COSTING",'DF20002'!A:A,0)) -> 113.72833 | K3: 185 | L3: 1000 | M3: =65/H3 -> 132.99233
A4: 3 | C4: DF20003 | D4: WALL MOUNTED BEDSIDE SHELF | E4: 45X35X23 | F4: 18X14X9 | G4: 50X40X28 | H4: ='DF20003'!E22 -> 0.056 | I4: =INDEX('DF20003'!H:H,MATCH("TOTAL COSTING",'DF20003'!A:A,0)) -> 26.343361 | J4: =INDEX('DF20003'!H:H,MATCH("PARAMETRIC COSTING",'DF20003'!A:A,0)) -> 22.929659 | K4: 40 | L4: 380 | M4: =65/H4 -> 1160.7143
A5: 4 | C5: DF20004 | D5: SOLID WOOD DINING TABLE 6 SEATER | E5: 180X90X76 | F5: 71X35X30 | G5: 185X95X81 | H5: ='DF20004'!E24 -> 1.423575 | I5: =INDEX('DF20004'!H:H,MATCH("TOTAL COSTING",'DF20004'!A:A,0)) -> 241.38886 | J5: =INDEX('DF20004'!H:H,MATCH("PARAMETRIC COSTING",'DF20004'!A:A,0)) -> 213.04548 | K5: 260 | L5: 1300 | M5: =65/H5 -> 45.659695
A6: 5 | C6: DF20005 | D6: ROUND COFFEE TABLE | E6: 80X80X42 | F6: 31X31X17 | G6: 85X85X47 | H6: ='DF20005'!E24 -> 0.339575 | I6: =INDEX('DF20005'!H:H,MATCH("TOTAL COSTING",'DF20005'!A:A,0)) -> 70.078167 | J6: =INDEX('DF20005'!H:H,MATCH("PARAMETRIC COSTING",'DF20005'!A:A,0)) -> 61.387169 | K6: 95 | L6: 550 | M6: =65/H6 -> 191.41574
A7: 6 | C7: DF20006 | D7: CONSOLE TABLE WITH 2 DRAWERS | E7: 120X38X78 | F7: 47X15X31 | G7: 125X43X83 | H7: ='DF20006'!E24 -> 0.446125 | I7: =INDEX('DF20006'!H:H,MATCH("TOTAL COSTING",'DF20006'!A:A,0)) -> 90.329691 | J7: =INDEX('DF20006'!H:H,MATCH("PARAMETRIC COSTING",'DF20006'!A:A,0)) -> 79.261541 | K7: 120 | L7: 650 | M7: =65/H7 -> 145.69908
A8: 7 | C8: DF20007 | D8: SLATTED DINING CHAIR | E8: 45X52X88 | F8: 18X20X35 | G8: 50X57X93 | H8: ='DF20007'!E24 -> 0.26505 | I8: =INDEX('DF20007'!H:H,MATCH("TOTAL COSTING",'DF20007'!A:A,0)) -> 49.661866 | J8: =INDEX('DF20007'!H:H,MATCH("PARAMETRIC COSTING",'DF20007'!A:A,0)) -> 43.656033 | K8: 55 | L8: 420 | M8: =65/H8 -> 245.23675
A9: 8 | C9: DF20008 | D9: COUNTER BAR STOOL | E9: 40X40X75 | F9: 16X16X30 | G9: 45X45X80 | H9: ='DF20008'!E24 -> 0.162 | I9: =INDEX('DF20008'!H:H,MATCH("TOTAL COSTING",'DF20008'!A:A,0)) -> 39.786566 | J9: =INDEX('DF20008'!H:H,MATCH("PARAMETRIC COSTING",'DF20008'!A:A,0)) -> 35.008696 | K9: 42 | L9: 300 | M9: =65/H9 -> 401.23457
A10: 9 | C10: DF20009 | D10: ENTRYWAY BENCH WITH SHELF | E10: 120X38X46 | F10: 47X15X18 | G10: 125X43X51 | H10: ='DF20009'!E24 -> 0.274125 | I10: =INDEX('DF20009'!H:H,MATCH("TOTAL COSTING",'DF20009'!A:A,0)) -> 57.378874 | J10: =INDEX('DF20009'!H:H,MATCH("PARAMETRIC COSTING",'DF20009'!A:A,0)) -> 50.238264 | K10: 85 | L10: 500 | M10: =65/H10 -> 237.1181
A11: 10 | C11: DF20010 | D11: FIVE TIER BOOKSHELF | E11: 80X35X180 | F11: 31X14X71 | G11: 85X40X185 | H11: ='DF20010'!E27 -> 0.629 | I11: =INDEX('DF20010'!H:H,MATCH("TOTAL COSTING",'DF20010'!A:A,0)) -> 149.62154 | J11: =INDEX('DF20010'!H:H,MATCH("PARAMETRIC COSTING",'DF20010'!A:A,0)) -> 130.46311 | K11: 150 | L11: 800 | M11: =65/H11 -> 103.33863
A12: 11 | C12: DF20011 | D12: TV UNIT 2 DOOR 1 DRAWER | E12: 140X40X55 | F12: 55X16X22 | G12: 145X45X60 | H12: ='DF20011'!E27 -> 0.3915 | I12: =INDEX('DF20011'!H:H,MATCH("TOTAL COSTING",'DF20011'!A:A,0)) -> 115.85306 | J12: =INDEX('DF20011'!H:H,MATCH("PARAMETRIC COSTING",'DF20011'!A:A,0)) -> 100.54134 | K12: 145 | L12: 750 | M12: =65/H12 -> 166.0281
A13: 12 | C13: DF20012 | D13: NEST OF 2 SIDE TABLES | E13: 50X50X55 | F13: 20X20X22 | G13: 55X55X60 | H13: ='DF20012'!E24 -> 0.1815 | I13: =INDEX('DF20012'!H:H,MATCH("TOTAL COSTING",'DF20012'!A:A,0)) -> 41.61849 | J13: =INDEX('DF20012'!H:H,MATCH("PARAMETRIC COSTING",'DF20012'!A:A,0)) -> 36.330445 | K13: 60 | L13: 400 | M13: =65/H13 -> 358.12672
A14: 13 | C14: DF20013 | D14: BAR CABINET WITH IRON FRAME | E14: 90X45X110 | F14: 35X18X43 | G14: 95X50X115 | H14: ='DF20013'!E27 -> 0.54625 | I14: =INDEX('DF20013'!H:H,MATCH("TOTAL COSTING",'DF20013'!A:A,0)) -> 154.86573 | J14: =INDEX('DF20013'!H:H,MATCH("PARAMETRIC COSTING",'DF20013'!A:A,0)) -> 135.50866 | K14: 220 | L14: 1050 | M14: =65/H14 -> 118.99314
A15: 14 | C15: DF20014 | D15: CANE DOOR CABINET | E15: 80X40X120 | F15: 31X16X47 | G15: 85X45X125 | H15: ='DF20014'!E27 -> 0.478125 | I15: =INDEX('DF20014'!H:H,MATCH("TOTAL COSTING",'DF20014'!A:A,0)) -> 122.61362 | J15: =INDEX('DF20014'!H:H,MATCH("PARAMETRIC COSTING",'DF20014'!A:A,0)) -> 106.76072 | K15: 190 | L15: 950 | M15: =65/H15 -> 135.94771
A16: 15 | C16: DF20015 | D16: FLUTED NIGHT STAND | E16: 45X40X60 | F16: 18X16X24 | G16: 50X45X65 | H16: ='DF20015'!E27 -> 0.14625 | I16: =INDEX('DF20015'!H:H,MATCH("TOTAL COSTING",'DF20015'!A:A,0)) -> 48.749904 | J16: =INDEX('DF20015'!H:H,MATCH("PARAMETRIC COSTING",'DF20015'!A:A,0)) -> 42.250065 | K16: 58 | L16: 380 | M16: =65/H16 -> 444.44444
A17: 16 | C17: DF20016 | D17: MIRROR WITH CARVED FRAME | E17: 70X4X100 | F17: 28X2X39 | G17: 75X9X105 | H17: ='DF20016'!E22 -> 0.070875 | I17: =INDEX('DF20016'!H:H,MATCH("TOTAL COSTING",'DF20016'!A:A,0)) -> 37.216084 | J17: =INDEX('DF20016'!H:H,MATCH("PARAMETRIC COSTING",'DF20016'!A:A,0)) -> 32.857697 | K17: 65 | L17: 350 | M17: =65/H17 -> 917.10758
A18: 17 | C18: DF20017 | D18: KIDS STUDY DESK | E18: 100X50X75 | F18: 39X20X30 | G18: 105X55X80 | H18: ='DF20017'!E24 -> 0.462 | I18: =INDEX('DF20017'!H:H,MATCH("TOTAL COSTING",'DF20017'!A:A,0)) -> 88.60343 | J18: =INDEX('DF20017'!H:H,MATCH("PARAMETRIC COSTING",'DF20017'!A:A,0)) -> 77.8607 | K18: 110 | L18: 600 | M18: =65/H18 -> 140.69264
A19: 18 | C19: DF20018 | D19: DRESSING TABLE WITH MIRROR | E19: 110X40X150 | F19: 43X16X59 | G19: 115X45X155 | H19: ='DF20018'!E27 -> 0.802125 | I19: =INDEX('DF20018'!H:H,MATCH("TOTAL COSTING",'DF20018'!A:A,0)) -> 193.10086 | J19: =INDEX('DF20018'!H:H,MATCH("PARAMETRIC COSTING",'DF20018'!A:A,0)) -> 169.06621 | K19: 210 | L19: 1000 | M19: =65/H19 -> 81.034751
A20: 19 | C20: DF20019 | D20: COAT RACK 6 HOOKS | E20: 100X8X30 | F20: 39X3X12 | G20: 105X13X35 | H20: ='DF20019'!E22 -> 0.047775 | I20: =INDEX('DF20019'!H:H,MATCH("TOTAL COSTING",'DF20019'!A:A,0)) -> 15.604584 | J20: =INDEX('DF20019'!H:H,MATCH("PARAMETRIC COSTING",'DF20019'!A:A,0)) -> 13.669436 | K20: 25 | L20: 150 | M20: =65/H20 -> 1360.5442
A21: 20 | C21: DF20020 | D21: HERRINGBONE COFFEE TABLE | E21: 110X60X40 | F21: 43X24X16 | G21: 115X65X45 | H21: ='DF20020'!E24 -> 0.336375 | I21: =INDEX('DF20020'!H:H,MATCH("TOTAL COSTING",'DF20020'!A:A,0)) -> 75.999832 | J21: =INDEX('DF20020'!H:H,MATCH("PARAMETRIC COSTING",'DF20020'!A:A,0)) -> 66.514135 | K21: 135 | L21: 700 | M21: =65/H21 -> 193.23671
A22: 21 | C22: DF20021 | D22: TURNED LEG SIDE TABLE | E22: 45X45X55 | F22: 18X18X22 | G22: 50X50X60 | H22: ='DF20021'!E25 -> 0.15 | I22: =INDEX('DF20021'!H:H,MATCH("TOTAL COSTING",'DF20021'!A:A,0)) -> 40.301526 | J22: =INDEX('DF20021'!H:H,MATCH("PARAMETRIC COSTING",'DF20021'!A:A,0)) -> 35.298892 | K22: 48 | L22: 320 | M22: =65/H22 -> 433.33333
A23: 22 | C23: DF20022 | D23: WINE RACK 12 BOTTLE | E23: 45X35X90 | F23: 18X14X35 | G23: 50X40X95 | H23: ='DF20022'!E27 -> 0.19 | I23: =INDEX('DF20022'!H:H,MATCH("TOTAL COSTING",'DF20022'!A:A,0)) -> 55.964214 | J23: =INDEX('DF20022'!H:H,MATCH("PARAMETRIC COSTING",'DF20022'!A:A,0)) -> 48.514119 | K23: 70 | L23: 400 | M23: =65/H23 -> 342.10526
A24: 23 | C24: DF20023 | D24: MARBLE TOP SIDE TABLE | E24: 50X50X55 | F24: 20X20X22 | G24: 55X55X60 | H24: ='DF20023'!E24 -> 0.1815 | I24: =INDEX('DF20023'!H:H,MATCH("TOTAL COSTING",'DF20023'!A:A,0)) -> 51.97849 | J24: =INDEX('DF20023'!H:H,MATCH("PARAMETRIC COSTING",'DF20023'!A:A,0)) -> 45.719932 | K24: 85 | L24: 380 | M24: =65/H24 -> 358.12672
A25: 24 | C25: DF20024 | D25: SHOE CABINET 3 TIER | E25: 90X35X100 | F25: 35X14X39 | G25: 95X40X105 | H25: ='DF20024'!E27 -> 0.399 | I25: =INDEX('DF20024'!H:H,MATCH("TOTAL COSTING",'DF20024'!A:A,0)) -> 101.80907 | J25: =INDEX('DF20024'!H:H,MATCH("PARAMETRIC COSTING",'DF20024'!A:A,0)) -> 88.67243 | K25: 125 | L25: 650 | M25: =65/H25 -> 162.90727

Sheet RATE
A1: LENGTH | B1: RATE
A2: 6 | B2: 42
A3: 7 | B3: 42
A4: 8 | B4: 42
A5: 9 | B5: 42
A6: 10 | B6: 42
A7: 11 | B7: 42
A8: 12 | B8: 42
A9: 13 | B9: 42
A10: 14 | B10: 42
A11: 15 | B11: 42
A12: 16 | B12: 42
A13: 17 | B13: 42
... A146: 150 | B146: 72

Sheet DF20001
D1: DESCRIPTION | F1: ='PRODUCT LIST'!D2 -> MANGO WOOD 4 DOOR SIDEBOARD
D2: PRODUCT CODE | F2: ='PRODUCT LIST'!C2 -> DF20001
B3: L | C3: W | D3: H | E3: CBM | F3: LOADABILITY
A4: PRODUCT SIZE | B4: =INDEX('PRODUCT LIST'!E:E,MATCH(F2,'PRODUCT LIST'!C:C,0)) -> 155X45X85
A5: PACKING SIZE | B5: =INDEX('PRODUCT LIST'!G:G,MATCH(F2,'PRODUCT LIST'!C:C,0)) -> 160X50X90
A6: CBM | B6: 160 | C6: 50 | D6: 90 | E6: =B6*C6*D6/1000000 -> 0.72 | F6: =65/E6 -> 90.277778
A7: L | B7: W | C7: H | D7: QTY | E7: SFT | F7: RATE | G7: TOTAL
A8: 63 | B8: 19 | C8: 1 | D8: 1 | E8: =SUM(A8*B8*C8/144*D8) -> 8.3125 | F8: =INDEX(RATE!B:B,MATCH(A8,RATE!A:A,0)) -> 62 | G8: =SUM(E8*F8) -> 515.375
A9: 34 | B9: 18 | C9: 1 | D9: 2 | E9: =SUM(A9*B9*C9/144*D9) -> 8.5 | F9: =INDEX(RATE!B:B,MATCH(A9,RATE!A:A,0)) -> 52 | G9: =SUM(E9*F9) -> 442
A10: 61 | B10: 18 | C10: 1 | D10: 2 | E10: =SUM(A10*B10*C10/144*D10) -> 15.25 | F10: =INDEX(RATE!B:B,MATCH(A10,RATE!A:A,0)) -> 62 | G10: =SUM(E10*F10) -> 945.5
A11: 61 | B11: 33 | C11: 0.5 | D11: 1 | E11: =SUM(A11*B11*C11/144*D11) -> 6.9895833 | F11: =INDEX(RATE!B:B,MATCH(A11,RATE!A:A,0)) -> 62 | G11: =SUM(E11*F11) -> 433.35417
A12: 33 | B12: 3 | C12: 1 | D12: 4 | E12: =SUM(A12*B12*C12/144*D12) -> 2.75 | F12: =INDEX(RATE!B:B,MATCH(A12,RATE!A:A,0)) -> 52 | G12: =SUM(E12*F12) -> 143
A13: 6 | B13: 3 | C13: 3 | D13: 4 | E13: =SUM(A13*B13*C13/144*D13) -> 1.5 | F13: =INDEX(RATE!B:B,MATCH(A13,RATE!A:A,0)) -> 42 | G13: =SUM(E13*F13) -> 63
A14: 61 | B14: 3 | C14: 1 | D14: 2 | E14: =SUM(A14*B14*C14/144*D14) -> 2.5416667 | F14: =INDEX(RATE!B:B,MATCH(A14,RATE!A:A,0)) -> 62 | G14: =SUM(E14*F14) -> 157.58333
A15: TOTAL WOOD | E15: =SUM(E8:E14) -> 45.84375 | G15: =SUM(G8:G14) -> 2699.8125
A16: WASTAGE 20% | E16: =+E15*0.2 -> 9.16875 | G16: =+G15*0.2 -> 539.9625
A17: TOTAL WOOD CONSUMP. | E17: =SUM(E15:E16) -> 55.0125 | G17: =SUM(G15:G16) -> 3239.775
A18: WAGES | G18: =INDEX('PRODUCT LIST'!L:L,MATCH(F2,'PRODUCT LIST'!C:C,0)) -> 1100
A19: KFD 8% | G19: =G17*8% -> 259.182
A20: TOTAL | G20: =SUM(G17:G19) -> 4598.957
A21: TRAD MARGIN/ 10% | G21: =G20*10% -> 459.8957
A22: TOTAL PURCHASE | G22: =G21+G20 -> 5058.8527
A23: KNOBS/HANDLE | C23: 4 | D23: PC | F23: 35 | G23: =C23*F23 -> 140
A24: TILE | C24: 0 | D24: SQ.FT | F24: 180 | G24: =C24*F24 -> 0
A25: IRON | C25: 0 | D25: KG | F25: 150 | G25: =C25*F25 -> 0
A26: CNC | C26: 0 | D26: MIN | F26: 2 | G26: =C26*F26 -> 0
A27: POLISH P & F | D27: FIX | E27: =E6 -> 0.72 | F27: =65/E27 -> 90.277778 | G27: =350000/F27 -> 3876.9231
A28: TOTAL | G28: =SUM(G22:G27) -> 9075.7758 | H28: =+G28/78 -> 116.3561 | I28: @78
A29: OH 15% | G29: =G28*15% -> 1361.3664
A30: MISC 15% | G30: =G28*15% -> 1361.3664
A31: TOTAL | G31: =SUM(G28:G30) -> 11798.509 | H31: =+G31/78 -> 151.26293
A32: MARGIN 20% | G32: =G31*0.2 -> 2359.7017
A33: TOTAL COSTING | G33: =G31+G32 -> 14158.21 | H33: =+G33/78 -> 181.51552 | I33: @78
A34: PARAMETRIC COSTING | G34: =G20+G23+G24+G25+G26+G27+G29+G32 -> 12336.948 | H34: =+G34/78 -> 158.166 | I34: @78

Sheet DF20002
D1: DESCRIPTION | F1: ='PRODUCT LIST'!D3 -> ACACIA 6 DRAWER CHEST
D2: PRODUCT CODE | F2: ='PRODUCT LIST'!C3 -> DF20002
B3: L | C3: W | D3: H | E3: CBM | F3: LOADABILITY
A4: PRODUCT SIZE | B4: =INDEX('PRODUCT LIST'!E:E,MATCH(F2,'PRODUCT LIST'!C:C,0)) -> 110X45X80
A5: PACKING SIZE | B5: =INDEX('PRODUCT LIST'!G:G,MATCH(F2,'PRODUCT LIST'!C:C,0)) -> 115X50X85
A6: CBM | B6: 115 | C6: 50 | D6: 85 | E6: =B6*C6*D6/1000000 -> 0.48875 | F6: =65/E6 -> 132.99233
A7: L | B7: W | C7: H | D7: QTY | E7: SFT | F7: RATE | G7: TOTAL
A8: 45 | B8: 19 | C8: 1 | D8: 1 | E8: =SUM(A8*B8*C8/144*D8) -> 5.9375 | F8: =INDEX(RATE!B:B,MATCH(A8,RATE!A:A,0)) -> 52 | G8: =SUM(E8*F8) -> 308.75
A9: 32 | B9: 18 | C9: 1 | D9: 2 | E9: =SUM(A9*B9*C9/144*D9) -> 8 | F9: =INDEX(RATE!B:B,MATCH(A9,RATE!A:A,0)) -> 52 | G9: =SUM(E9*F9) -> 416
A10: 43 | B10: 18 | C10: 1 | D10: 2 | E10: =SUM(A10*B10*C10/144*D10) -> 10.75 | F10: =INDEX(RATE!B:B,MATCH(A10,RATE!A:A,0)) -> 52 | G10: =SUM(E10*F10) -> 559
A11: 43 | B11: 31 | C11: 0.5 | D11: 1 | E11: =SUM(A11*B11*C11/144*D11) -> 4.6284722 | F11: =INDEX(RATE!B:B,MATCH(A11,RATE!A:A,0)) -> 52 | G11: =SUM(E11*F11) -> 240.68056
A12: 31 | B12: 3 | C12: 1 | D12: 4 | E12: =SUM(A12*B12*C12/144*D12) -> 2.5833333 | F12: =INDEX(RATE!B:B,MATCH(A12,RATE!A:A,0)) -> 52 | G12: =SUM(E12*F12) -> 134.33333
A13: 6 | B13: 3 | C13: 3 | D13: 4 | E13: =SUM(A13*B13*C13/144*D13) -> 1.5 | F13: =INDEX(RATE!B:B,MATCH(A13,RATE!A:A,0)) -> 42 | G13: =SUM(E13*F13) -> 63
A14: 43 | B14: 3 | C14: 1 | D14: 2 | E14: =SUM(A14*B14*C14/144*D14) -> 1.7916667 | F14: =INDEX(RATE!B:B,MATCH(A14,RATE!A:A,0)) -> 52 | G14: =SUM(E14*F14) -> 93.166667
A15: TOTAL WOOD | E15: =SUM(E8:E14) -> 35.190972 | G15: =SUM(G8:G14) -> 1814.9306
A16: WASTAGE 20% | E16: =+E15*0.2 -> 7.0381944 | G16: =+G15*0.2 -> 362.98611
A17: TOTAL WOOD CONSUMP. | E17: =SUM(E15:E16) -> 42.229167 | G17: =SUM(G15:G16) -> 2177.9167
A18: WAGES | G18: =INDEX('PRODUCT LIST'!L:L,MATCH(F2,'PRODUCT LIST'!C:C,0)) -> 1000
A19: KFD 8% | G19: =G17*8% -> 174.23333
A20: TOTAL | G20: =SUM(G17:G19) -> 3352.15
A21: TRAD MARGIN/ 10% | G21: =G20*10% -> 335.215
A22: TOTAL PURCHASE | G22: =G21+G20 -> 3687.365
A23: KNOBS/HANDLE | C23: 6 | D23: PC | F23: 35 | G23: =C23*F23 -> 210
A24: TILE | C24: 0 | D24: SQ.FT | F24: 180 | G24: =C24*F24 -> 0
A25: IRON | C25: 0 | D25: KG | F25: 150 | G25: =C25*F25 -> 0
A26: CNC | C26: 0 | D26: MIN | F26: 2 | G26: =C26*F26 -> 0
A27: POLISH P & F | D27: FIX | E27: =E6 -> 0.48875 | F27: =65/E27 -> 132.99233 | G27: =350000/F27 -> 2631.7308
A28: TOTAL | G28: =SUM(G22:G27) -> 6529.0958 | H28: =+G28/78 -> 83.706356 | I28: @78
A29: OH 15% | G29: =G28*15% -> 979.36437
A30: MISC 15% | G30: =G28*15% -> 979.36437
A31: TOTAL | G31: =SUM(G28:G30) -> 8487.8245 | H31: =+G31/78 -> 108.81826
A32: MARGIN 20% | G32: =G31*0.2 -> 1697.5649
A33: TOTAL COSTING | G33: =G31+G32 -> 10185.389 | H33: =+G33/78 -> 130.58192 | I33: @78
A34: PARAMETRIC COSTING | G34: =G20+G23+G24+G25+G26+G27+G29+G32 -> 8870.81 | H34: =+G34/78 -> 113.72833 | I34: @78

Sheet DF20003
D1: DESCRIPTION | F1: ='PRODUCT LIST'!D4 -> WALL MOUNTED BEDSIDE SHELF
D2: PRODUCT CODE | F2: ='PRODUCT LIST'!C4 -> DF20003
B3: L | C3: W | D3: H | E3: CBM | F3: LOADABILITY
A4: PRODUCT SIZE | B4: =INDEX('PRODUCT LIST'!E:E,MATCH(F2,'PRODUCT LIST'!C:C,0)) -> 45X35X23
A5: PACKING SIZE | B5: =INDEX('PRODUCT LIST'!G:G,MATCH(F2,'PRODUCT LIST'!C:C,0)) -> 50X40X28
A6: CBM | B6: 50 | C6: 40 | D6: 28 | E6: =B6*C6*D6/1000000 -> 0.056 | F6: =65/E6 -> 1160.7143
A7: L | B7: W | C7: H | D7: QTY | E7: SFT | F7: RATE | G7: TOTAL
A8: 19 | B8: 14 | C8: 1 | D8: 2 | E8: =SUM(A8*B8*C8/144*D8) -> 3.6944444 | F8: =INDEX(RATE!B:B,MATCH(A8,RATE!A:A,0)) -> 42 | G8: =SUM(E8*F8) -> 155.16667
A9: 10 | B9: 14 | C9: 1 | D9: 2 | E9: =SUM(A9*B9*C9/144*D9) -> 1.9444444 | F9: =INDEX(RATE!B:B,MATCH(A9,RATE!A:A,0)) -> 42 | G9: =SUM(E9*F9) -> 81.666667
A10: TOTAL WOOD | E10: =SUM(E8:E9) -> 5.6388889 | G10: =SUM(G8:G9) -> 236.83333
A11: WASTAGE 20% | E11: =+E10*0.2 -> 1.1277778 | G11: =+G10*0.2 -> 47.366667
A12: TOTAL WOOD CONSUMP. | E12: =SUM(E10:E11) -> 6.7666667 | G12: =SUM(G10:G11) -> 284.2
A13: WAGES | G13: =INDEX('PRODUCT LIST'!L:L,MATCH(F2,'PRODUCT LIST'!C:C,0)) -> 380
A14: KFD 8% | G14: =G12*8% -> 22.736
A15: TOTAL | G15: =SUM(G12:G14) -> 686.936
A16: TRAD MARGIN/ 10% | G16: =G15*10% -> 68.6936
A17: TOTAL PURCHASE | G17: =G16+G15 -> 755.6296
A18: KNOBS/HANDLE | C18: 1 | D18: PC | F18: 35 | G18: =C18*F18 -> 35
A19: TILE | C19: 0 | D19: SQ.FT | F19: 180 | G19: =C19*F19 -> 0
A20: IRON | C20: 1.5 | D20: KG | F20: 150 | G20: =C20*F20 -> 225
A21: CNC | C21: 0 | D21: MIN | F21: 2 | G21: =C21*F21 -> 0
A22: POLISH P & F | D22: FIX | E22: =E6 -> 0.056 | F22: =65/E22 -> 1160.7143 | G22: =350000/F22 -> 301.53846
A23: TOTAL | G23: =SUM(G17:G22) -> 1317.1681 | H23: =+G23/78 -> 16.88677 | I23: @78
A24: OH 15% | G24: =G23*15% -> 197.57521
A25: MISC 15% | G25: =G23*15% -> 197.57521
A26: TOTAL | G26: =SUM(G23:G25) -> 1712.3185 | H26: =+G26/78 -> 21.952801
A27: MARGIN 20% | G27: =G26*0.2 -> 342.4637
A28: TOTAL COSTING | G28: =G26+G27 -> 2054.7822 | H28: =+G28/78 -> 26.343361 | I28: @78
A29: PARAMETRIC COSTING | G29: =G15+G18+G19+G20+G21+G22+G24+G27 -> 1788.5134 | H29: =+G29/78 -> 22.929659 | I29: @78

Sheet DF20004
D1: DESCRIPTION | F1: ='PRODUCT LIST'!D5 -> SOLID WOOD DINING TABLE 6 SEATER
D2: PRODUCT CODE | F2: ='PRODUCT LIST'!C5 -> DF20004
B3: L | C3: W | D3: H | E3: CBM | F3: LOADABILITY
A4: PRODUCT SIZE | B4: =INDEX('PRODUCT LIST'!E:E,MATCH(F2,'PRODUCT LIST'!C:C,0)) -> 180X90X76
A5: PACKING SIZE | B5: =INDEX('PRODUCT LIST'!G:G,MATCH(F2,'PRODUCT LIST'!C:C,0)) -> 185X95X81
A6: CBM | B6: 185 | C6: 95 | D6: 81 | E6: =B6*C6*D6/1000000 -> 1.423575 | F6: =65/E6 -> 45.659695
A7: L | B7: W | C7: H | D7: QTY | E7: SFT | F7: RATE | G7: TOTAL
A8: 73 | B8: 37 | C8: 1 | D8: 1 | E8: =SUM(A8*B8*C8/144*D8) -> 18.756944 | F8: =INDEX(RATE!B:B,MATCH(A8,RATE!A:A,0)) -> 72 | G8: =SUM(E8*F8) -> 1350.5
A9: 30 | B9: 3 | C9: 3 | D9: 4 | E9: =SUM(A9*B9*C9/144*D9) -> 7.5 | F9: =INDEX(RATE!B:B,MATCH(A9,RATE!A:A,0)) -> 52 | G9: =SUM(E9*F9) -> 390
A10: 71 | B10: 4 | C10: 1 | D10: 2 | E10: =SUM(A10*B10*C10/144*D10) -> 3.9444444 | F10: =INDEX(RATE!B:B,MATCH(A10,RATE!A:A,0)) -> 62 | G10: =SUM(E10*F10) -> 244.55556
A11: 35 | B11: 4 | C11: 1 | D11: 2 | E11: =SUM(A11*B11*C11/144*D11) -> 1.9444444 | F11: =INDEX(RATE!B:B,MATCH(A11,RATE!A:A,0)) -> 52 | G11: =SUM(E11*F11) -> 101.11111
A12: TOTAL WOOD | E12: =SUM(E8:E11) -> 32.145833 | G12: =SUM(G8:G11) -> 2086.1667
A13: WASTAGE 20% | E13: =+E12*0.2 -> 6.4291667 | G13: =+G12*0.2 -> 417.23333
A14: TOTAL WOOD CONSUMP. | E14: =SUM(E12:E13) -> 38.575 | G14: =SUM(G12:G13) -> 2503.4
A15: WAGES | G15: =INDEX('PRODUCT LIST'!L:L,MATCH(F2,'PRODUCT LIST'!C:C,0)) -> 1300
A16: KFD 8% | G16: =G14*8% -> 200.272
A17: TOTAL | G17: =SUM(G14:G16) -> 4003.672
A18: TRAD MARGIN/ 10% | G18: =G17*10% -> 400.3672
A19: TOTAL PURCHASE | G19: =G18+G17 -> 4404.0392
A20: KNOBS/HANDLE | C20: 0 | D20: PC | F20: 35 | G20: =C20*F20 -> 0
A21: TILE | C21: 0 | D21: SQ.FT | F21: 180 | G21: =C21*F21 -> 0
A22: IRON | C22: 0 | D22: KG | F22: 150 | G22: =C22*F22 -> 0
A23: CNC | C23: 0 | D23: MIN | F23: 2 | G23: =C23*F23 -> 0
A24: POLISH P & F | D24: FIX | E24: =E6 -> 1.423575 | F24: =65/E24 -> 45.659695 | G24: =350000/F24 -> 7665.4038
A25: TOTAL | G25: =SUM(G19:G24) -> 12069.443 | H25: =+G25/78 -> 154.73645 | I25: @78
A26: OH 15% | G26: =G25*15% -> 1810.4165
A27: MISC 15% | G27: =G25*15% -> 1810.4165
A28: TOTAL | G28: =SUM(G25:G27) -> 15690.276 | H28: =+G28/78 -> 201.15738
A29: MARGIN 20% | G29: =G28*0.2 -> 3138.0552
A30: TOTAL COSTING | G30: =G28+G29 -> 18828.331 | H30: =+G30/78 -> 241.38886 | I30: @78
A31: PARAMETRIC COSTING | G31: =G17+G20+G21+G22+G23+G24+G26+G29 -> 16617.547 | H31: =+G31/78 -> 213.04548 | I31: @78

Sheet DF20005
D1: DESCRIPTION | F1: ='PRODUCT LIST'!D6 -> ROUND COFFEE TABLE
D2: PRODUCT CODE | F2: ='PRODUCT LIST'!C6 -> DF20005
B3: L | C3: W | D3: H | E3: CBM | F3: LOADABILITY
A4: PRODUCT SIZE | B4: =INDEX('PRODUCT LIST'!E:E,MATCH(F2,'PRODUCT LIST'!C:C,0)) -> 80X80X42
A5: PACKING SIZE | B5: =INDEX('PRODUCT LIST'!G:G,MATCH(F2,'PRODUCT LIST'!C:C,0)) -> 85X85X47
A6: CBM | B6: 85 | C6: 85 | D6: 47 | E6: =B6*C6*D6/1000000 -> 0.339575 | F6: =65/E6 -> 191.41574
A7: L | B7: W | C7: H | D7: QTY | E7: SFT | F7: RATE | G7: TOTAL
A8: 33 | B8: 33 | C8: 1 | D8: 1 | E8: =SUM(A8*B8*C8/144*D8) -> 7.5625 | F8: =INDEX(RATE!B:B,MATCH(A8,RATE!A:A,0)) -> 52 | G8: =SUM(E8*F8) -> 393.25
A9: 17 | B9: 3 | C9: 3 | D9: 4 | E9: =SUM(A9*B9*C9/144*D9) -> 4.25 | F9: =INDEX(RATE!B:B,MATCH(A9,RATE!A:A,0)) -> 42 | G9: =SUM(E9*F9) -> 178.5
A10: 31 | B10: 4 | C10: 1 | D10: 2 | E10: =SUM(A10*B10*C10/144*D10) -> 1.7222222 | F10: =INDEX(RATE!B:B,MATCH(A10,RATE!A:A,0)) -> 52 | G10: =SUM(E10*F10) -> 89.555556
A11: 31 | B11: 4 | C11: 1 | D11: 2 | E11: =SUM(A11*B11*C11/144*D11) -> 1.7222222 | F11: =INDEX(RATE!B:B,MATCH(A11,RATE!A:A,0)) -> 52 | G11: =SUM(E11*F11) -> 89.555556
A12: TOTAL WOOD | E12: =SUM(E8:E11) -> 15.256944 | G12: =SUM(G8:G11) -> 750.86111
A13: WASTAGE 20% | E13: =+E12*0.2 -> 3.0513889 | G13: =+G12*0.2 -> 150.17222
A14: TOTAL WOOD CONSUMP. | E14: =SUM(E12:E13) -> 18.308333 | G14: =SUM(G12:G13) -> 901.03333
A15: WAGES | G15: =INDEX('PRODUCT LIST'!L:L,MATCH(F2,'PRODUCT LIST'!C:C,0)) -> 550
A16: KFD 8% | G16: =G14*8% -> 72.082667
A17: TOTAL | G17: =SUM(G14:G16) -> 1523.116
A18: TRAD MARGIN/ 10% | G18: =G17*10% -> 152.3116
A19: TOTAL PURCHASE | G19: =G18+G17 -> 1675.4276
A20: KNOBS/HANDLE | C20: 0 | D20: PC | F20: 35 | G20: =C20*F20 -> 0
A21: TILE | C21: 0 | D21: SQ.FT | F21: 180 | G21: =C21*F21 -> 0
A22: IRON | C22: 0 | D22: KG | F22: 150 | G22: =C22*F22 -> 0
A23: CNC | C23: 0 | D23: MIN | F23: 2 | G23: =C23*F23 -> 0
A24: POLISH P & F | D24: FIX | E24: =E6 -> 0.339575 | F24: =65/E24 -> 191.41574 | G24: =350000/F24 -> 1828.4808
A25: TOTAL | G25: =SUM(G19:G24) -> 3503.9084 | H25: =+G25/78 -> 44.921902 | I25: @78
A26: OH 15% | G26: =G25*15% -> 525.58626
A27: MISC 15% | G27: =G25*15% -> 525.58626
A28: TOTAL | G28: =SUM(G25:G27) -> 4555.0809 | H28: =+G28/78 -> 58.398473
A29: MARGIN 20% | G29: =G28*0.2 -> 911.01618
A30: TOTAL COSTING | G30: =G28+G29 -> 5466.0971 | H30: =+G30/78 -> 70.078167 | I30: @78
A31: PARAMETRIC COSTING | G31: =G17+G20+G21+G22+G23+G24+G26+G29 -> 4788.1992 | H31: =+G31/78 -> 61.387169 | I31: @78

Sheet DF20006
D1: DESCRIPTION | F1: ='PRODUCT LIST'!D7 -> CONSOLE TABLE WITH 2 DRAWERS
D2: PRODUCT CODE | F2: ='PRODUCT LIST'!C7 -> DF20006
B3: L | C3: W | D3: H | E3: CBM | F3: LOADABILITY
A4: PRODUCT SIZE | B4: =INDEX('PRODUCT LIST'!E:E,MATCH(F2,'PRODUCT LIST'!C:C,0)) -> 120X38X78
A5: PACKING SIZE | B5: =INDEX('PRODUCT LIST'!G:G,MATCH(F2,'PRODUCT LIST'!C:C,0)) -> 125X43X83
A6: CBM | B6: 125 | C6: 43 | D6: 83 | E6: =B6*C6*D6/1000000 -> 0.446125 | F6: =65/E6 -> 145.69908
A7: L | B7: W | C7: H | D7: QTY | E7: SFT | F7: RATE | G7: TOTAL
A8: 49 | B8: 17 | C8: 1 | D8: 1 | E8: =SUM(A8*B8*C8/144*D8) -> 5.7847222 | F8: =INDEX(RATE!B:B,MATCH(A8,RATE!A:A,0)) -> 62 | G8: =SUM(E8*F8) -> 358.65278
A9: 31 | B9: 3 | C9: 3 | D9: 4 | E9: =SUM(A9*B9*C9/144*D9) -> 7.75 | F9: =INDEX(RATE!B:B,MATCH(A9,RATE!A:A,0)) -> 52 | G9: =SUM(E9*F9) -> 403
A10: 47 | B10: 4 | C10: 1 | D10: 2 | E10: =SUM(A10*B10*C10/144*D10) -> 2.6111111 | F10: =INDEX(RATE!B:B,MATCH(A10,RATE!A:A,0)) -> 52 | G10: =SUM(E10*F10) -> 135.77778
A11: 15 | B11: 4 | C11: 1 | D11: 2 | E11: =SUM(A11*B11*C11/144*D11) -> 0.83333333 | F11: =INDEX(RATE!B:B,MATCH(A11,RATE!A:A,0)) -> 42 | G11: =SUM(E11*F11) -> 35
A12: TOTAL WOOD | E12: =SUM(E8:E11) -> 16.979167 | G12: =SUM(G8:G11) -> 932.43056
A13: WASTAGE 20% | E13: =+E12*0.2 -> 3.3958333 | G13: =+G12*0.2 -> 186.48611
A14: TOTAL WOOD CONSUMP. | E14: =SUM(E12:E13) -> 20.375 | G14: =SUM(G12:G13) -> 1118.9167
A15: WAGES | G15: =INDEX('PRODUCT LIST'!L:L,MATCH(F2,'PRODUCT LIST'!C:C,0)) -> 650
A16: KFD 8% | G16: =G14*8% -> 89.513333
A17: TOTAL | G17: =SUM(G14:G16) -> 1858.43
A18: TRAD MARGIN/ 10% | G18: =G17*10% -> 185.843
A19: TOTAL PURCHASE | G19: =G18+G17 -> 2044.273
A20: KNOBS/HANDLE | C20: 2 | D20: PC | F20: 35 | G20: =C20*F20 -> 70
A21: TILE | C21: 0 | D21: SQ.FT | F21: 180 | G21: =C21*F21 -> 0
A22: IRON | C22: 0 | D22: KG | F22: 150 | G22: =C22*F22 -> 0
A23: CNC | C23: 0 | D23: MIN | F23: 2 | G23: =C23*F23 -> 0
A24: POLISH P & F | D24: FIX | E24: =E6 -> 0.446125 | F24: =65/E24 -> 145.69908 | G24: =350000/F24 -> 2402.2115
A25: TOTAL | G25: =SUM(G19:G24) -> 4516.4845 | H25: =+G25/78 -> 57.903648 | I25: @78
A26: OH 15% | G26: =G25*15% -> 677.47268
A27: MISC 15% | G27: =G25*15% -> 677.47268
A28: TOTAL | G28: =SUM(G25:G27) -> 5871.4299 | H28: =+G28/78 -> 75.274742
A29: MARGIN 20% | G29: =G28*0.2 -> 1174.286
A30: TOTAL COSTING | G30: =G28+G29 -> 7045.7159 | H30: =+G30/78 -> 90.329691 | I30: @78
A31: PARAMETRIC COSTING | G31: =G17+G20+G21+G22+G23+G24+G26+G29 -> 6182.4002 | H31: =+G31/78 -> 79.261541 | I31: @78

Sheet DF20007
D1: DESCRIPTION | F1: ='PRODUCT LIST'!D8 -> SLATTED DINING CHAIR
D2: PRODUCT CODE | F2: ='PRODUCT LIST'!C8 -> DF20007
B3: L | C3: W | D3: H | E3: CBM | F3: LOADABILITY
A4: PRODUCT SIZE | B4: =INDEX('PRODUCT LIST'!E:E,MATCH(F2,'PRODUCT LIST'!C:C,0)) -> 45X52X88
A5: PACKING SIZE | B5: =INDEX('PRODUCT LIST'!G:G,MATCH(F2,'PRODUCT LIST'!C:C,0)) -> 50X57X93
A6: CBM | B6: 50 | C6: 57 | D6: 93 | E6: =B6*C6*D6/1000000 -> 0.26505 | F6: =65/E6 -> 245.23675
A7: L | B7: W | C7: H | D7: QTY | E7: SFT | F7: RATE | G7: TOTAL
A8: 19 | B8: 21 | C8: 1 | D8: 1 | E8: =SUM(A8*B8*C8/144*D8) -> 2.7708333 | F8: =INDEX(RATE!B:B,MATCH(A8,RATE!A:A,0)) -> 42 | G8: =SUM(E8*F8) -> 116.375
A9: 35 | B9: 2 | C9: 2 | D9: 4 | E9: =SUM(A9*B9*C9/144*D9) -> 3.8888889 | F9: =INDEX(RATE!B:B,MATCH(A9,RATE!A:A,0)) -> 52 | G9: =SUM(E9*F9) -> 202.22222
A10: 18 | B10: 3 | C10: 1 | D10: 4 | E10: =SUM(A10*B10*C10/144*D10) -> 1.5 | F10: =INDEX(RATE!B:B,MATCH(A10,RATE!A:A,0)) -> 42 | G10: =SUM(E10*F10) -> 63
A11: 20 | B11: 3 | C11: 1 | D11: 2 | E11: =SUM(A11*B11*C11/144*D11) -> 0.83333333 | F11: =INDEX(RATE!B:B,MATCH(A11,RATE!A:A,0)) -> 42 | G11: =SUM(E11*F11) -> 35
A12: TOTAL WOOD | E12: =SUM(E8:E11) -> 8.9930556 | G12: =SUM(G8:G11) -> 416.59722
A13: WASTAGE 20% | E13: =+E12*0.2 -> 1.7986111 | G13: =+G12*0.2 -> 83.319444
A14: TOTAL WOOD CONSUMP. | E14: =SUM(E12:E13) -> 10.791667 | G14: =SUM(G12:G13) -> 499.91667
A15: WAGES | G15: =INDEX('PRODUCT LIST'!L:L,MATCH(F2,'PRODUCT LIST'!C:C,0)) -> 420
A16: KFD 8% | G16: =G14*8% -> 39.993333
A17: TOTAL | G17: =SUM(G14:G16) -> 959.91
A18: TRAD MARGIN/ 10% | G18: =G17*10% -> 95.991
A19: TOTAL PURCHASE | G19: =G18+G17 -> 1055.901
A20: KNOBS/HANDLE | C20: 0 | D20: PC | F20: 35 | G20: =C20*F20 -> 0
A21: TILE | C21: 0 | D21: SQ.FT | F21: 180 | G21: =C21*F21 -> 0
A22: IRON | C22: 0 | D22: KG | F22: 150 | G22: =C22*F22 -> 0
A23: CNC | C23: 0 | D23: MIN | F23: 2 | G23: =C23*F23 -> 0
A24: POLISH P & F | D24: FIX | E24: =E6 -> 0.26505 | F24: =65/E24 -> 245.23675 | G24: =350000/F24 -> 1427.1923
A25: TOTAL | G25: =SUM(G19:G24) -> 2483.0933 | H25: =+G25/78 -> 31.83453 | I25: @78
A26: OH 15% | G26: =G25*15% -> 372.464
A27: MISC 15% | G27: =G25*15% -> 372.464
A28: TOTAL | G28: =SUM(G25:G27) -> 3228.0213 | H28: =+G28/78 -> 41.384888
A29: MARGIN 20% | G29: =G28*0.2 -> 645.60426
A30: TOTAL COSTING | G30: =G28+G29 -> 3873.6256 | H30: =+G30/78 -> 49.661866 | I30: @78
A31: PARAMETRIC COSTING | G31: =G17+G20+G21+G22+G23+G24+G26+G29 -> 3405.1706 | H31: =+G31/78 -> 43.656033 | I31: @78

Sheet DF20008
D1: DESCRIPTION | F1: ='PRODUCT LIST'!D9 -> COUNTER BAR STOOL
D2: PRODUCT CODE | F2: ='PRODUCT LIST'!C9 -> DF20008
B3: L | C3: W | D3: H | E3: CBM | F3: LOADABILITY
A4: PRODUCT SIZE | B4: =INDEX('PRODUCT LIST'!E:E,MATCH(F2,'PRODUCT LIST'!C:C,0)) -> 40X40X75
A5: PACKING SIZE | B5: =INDEX('PRODUCT LIST'!G:G,MATCH(F2,'PRODUCT LIST'!C:C,0)) -> 45X45X80
A6: CBM | B6: 45 | C6: 45 | D6: 80 | E6: =B6*C6*D6/1000000 -> 0.162 | F6: =65/E6 -> 401.23457
A7: L | B7: W | C7: H | D7: QTY | E7: SFT | F7: RATE | G7: TOTAL
A8: 17 | B8: 17 | C8: 1 | D8: 1 | E8: =SUM(A8*B8*C8/144*D8) -> 2.0069444 | F8: =INDEX(RATE!B:B,MATCH(A8,RATE!A:A,0)) -> 42 | G8: =SUM(E8*F8) -> 84.291667
A9: 30 | B9: 2 | C9: 2 | D9: 4 | E9: =SUM(A9*B9*C9/144*D9) -> 3.3333333 | F9: =INDEX(RATE!B:B,MATCH(A9,RATE!A:A,0)) -> 52 | G9: =SUM(E9*F9) -> 173.33333
A10: 16 | B10: 3 | C10: 1 | D10: 4 | E10: =SUM(A10*B10*C10/144*D10) -> 1.3333333 | F10: =INDEX(RATE!B:B,MATCH(A10,RATE!A:A,0)) -> 42 | G10: =SUM(E10*F10) -> 56
A11: 16 | B11: 3 | C11: 1 | D11: 2 | E11: =SUM(A11*B11*C11/144*D11) -> 0.66666667 | F11: =INDEX(RATE!B:B,MATCH(A11,RATE!A:A,0)) -> 42 | G11: =SUM(E11*F11) -> 28
A12: TOTAL WOOD | E12: =SUM(E8:E11) -> 7.3402778 | G12: =SUM(G8:G11) -> 341.625
A13: WASTAGE 20% | E13: =+E12*0.2 -> 1.4680556 | G13: =+G12*0.2 -> 68.325
A14: TOTAL WOOD CONSUMP. | E14: =SUM(E12:E13) -> 8.8083333 | G14: =SUM(G12:G13) -> 409.95
A15: WAGES | G15: =INDEX('PRODUCT LIST'!L:L,MATCH(F2,'PRODUCT LIST'!C:C,0)) -> 300
A16: KFD 8% | G16: =G14*8% -> 32.796
A17: TOTAL | G17: =SUM(G14:G16) -> 742.746
A18: TRAD MARGIN/ 10% | G18: =G17*10% -> 74.2746
A19: TOTAL PURCHASE | G19: =G18+G17 -> 817.0206
A20: KNOBS/HANDLE | C20: 0 | D20: PC | F20: 35 | G20: =C20*F20 -> 0
A21: TILE | C21: 0 | D21: SQ.FT | F21: 180 | G21: =C21*F21 -> 0
A22: IRON | C22: 2 | D22: KG | F22: 150 | G22: =C22*F22 -> 300
A23: CNC | C23: 0 | D23: MIN | F23: 2 | G23: =C23*F23 -> 0
A24: POLISH P & F | D24: FIX | E24: =E6 -> 0.162 | F24: =65/E24 -> 401.23457 | G24: =350000/F24 -> 872.30769
A25: TOTAL | G25: =SUM(G19:G24) -> 1989.3283 | H25: =+G25/78 -> 25.504209 | I25: @78
A26: OH 15% | G26: =G25*15% -> 298.39924
A27: MISC 15% | G27: =G25*15% -> 298.39924
A28: TOTAL | G28: =SUM(G25:G27) -> 2586.1268 | H28: =+G28/78 -> 33.155472
A29: MARGIN 20% | G29: =G28*0.2 -> 517.22536
A30: TOTAL COSTING | G30: =G28+G29 -> 3103.3521 | H30: =+G30/78 -> 39.786566 | I30: @78
A31: PARAMETRIC COSTING | G31: =G17+G20+G21+G22+G23+G24+G26+G29 -> 2730.6783 | H31: =+G31/78 -> 35.008696 | I31: @78

Sheet DF20009
D1: DESCRIPTION | F1: ='PRODUCT LIST'!D10 -> ENTRYWAY BENCH WITH SHELF
D2: PRODUCT CODE | F2: ='PRODUCT LIST'!C10 -> DF20009
B3: L | C3: W | D3: H | E3: CBM | F3: LOADABILITY
A4: PRODUCT SIZE | B4: =INDEX('PRODUCT LIST'!E:E,MATCH(F2,'PRODUCT LIST'!C:C,0)) -> 120X38X46
A5: PACKING SIZE | B5: =INDEX('PRODUCT LIST'!G:G,MATCH(F2,'PRODUCT LIST'!C:C,0)) -> 125X43X51
A6: CBM | B6: 125 | C6: 43 | D6: 51 | E6: =B6*C6*D6/1000000 -> 0.274125 | F6: =65/E6 -> 237.1181
A7: L | B7: W | C7: H | D7: QTY | E7: SFT | F7: RATE | G7: TOTAL
A8: 48 | B8: 16 | C8: 1 | D8: 1 | E8: =SUM(A8*B8*C8/144*D8) -> 5.3333333 | F8: =INDEX(RATE!B:B,MATCH(A8,RATE!A:A,0)) -> 52 | G8: =SUM(E8*F8) -> 277.33333
A9: 18 | B9: 2 | C9: 2 | D9: 4 | E9: =SUM(A9*B9*C9/144*D9) -> 2 | F9: =INDEX(RATE!B:B,MATCH(A9,RATE!A:A,0)) -> 42 | G9: =SUM(E9*F9) -> 84
A10: 47 | B10: 3 | C10: 1 | D10: 4 | E10: =SUM(A10*B10*C10/144*D10) -> 3.9166667 | F10: =INDEX(RATE!B:B,MATCH(A10,RATE!A:A,0)) -> 52 | G10: =SUM(E10*F10) -> 203.66667
A11: 15 | B11: 3 | C11: 1 | D11: 2 | E11: =SUM(A11*B11*C11/144*D11) -> 0.625 | F11: =INDEX(RATE!B:B,MATCH(A11,RATE!A:A,0)) -> 42 | G11: =SUM(E11*F11) -> 26.25
A12: TOTAL WOOD | E12: =SUM(E8:E11) -> 11.875 | G12: =SUM(G8:G11) -> 591.25
A13: WASTAGE 20% | E13: =+E12*0.2 -> 2.375 | G13: =+G12*0.2 -> 118.25
A14: TOTAL WOOD CONSUMP. | E14: =SUM(E12:E13) -> 14.25 | G14: =SUM(G12:G13) -> 709.5
A15: WAGES | G15: =INDEX('PRODUCT LIST'!L:L,MATCH(F2,'PRODUCT LIST'!C:C,0)) -> 500
A16: KFD 8% | G16: =G14*8% -> 56.76
A17: TOTAL | G17: =SUM(G14:G16) -> 1266.26
A18: TRAD MARGIN/ 10% | G18: =G17*10% -> 126.626
A19: TOTAL PURCHASE | G19: =G18+G17 -> 1392.886
A20: KNOBS/HANDLE | C20: 0 | D20: PC | F20: 35 | G20: =C20*F20 -> 0
A21: TILE | C21: 0 | D21: SQ.FT | F21: 180 | G21: =C21*F21 -> 0
A22: IRON | C22: 0 | D22: KG | F22: 150 | G22: =C22*F22 -> 0
A23: CNC | C23: 0 | D23: MIN | F23: 2 | G23: =C23*F23 -> 0
A24: POLISH P & F | D24: FIX | E24: =E6 -> 0.274125 | F24: =65/E24 -> 237.1181 | G24: =350000/F24 -> 1476.0577
A25: TOTAL | G25: =SUM(G19:G24) -> 2868.9437 | H25: =+G25/78 -> 36.781329 | I25: @78
A26: OH 15% | G26: =G25*15% -> 430.34155
A27: MISC 15% | G27: =G25*15% -> 430.34155
A28: TOTAL | G28: =SUM(G25:G27) -> 3729.6268 | H28: =+G28/78 -> 47.815728
A29: MARGIN 20% | G29: =G28*0.2 -> 745.92536
A30: TOTAL COSTING | G30: =G28+G29 -> 4475.5522 | H30: =+G30/78 -> 57.378874 | I30: @78
A31: PARAMETRIC COSTING | G31: =G17+G20+G21+G22+G23+G24+G26+G29 -> 3918.5846 | H31: =+G31/78 -> 50.238264 | I31: @78

Sheet DF20010
D1: DESCRIPTION | F1: ='PRODUCT LIST'!D11 -> FIVE TIER BOOKSHELF
D2: PRODUCT CODE | F2: ='PRODUCT LIST'!C11 -> DF20010
B3: L | C3: W | D3: H | E3: CBM | F3: LOADABILITY
A4: PRODUCT SIZE | B4: =INDEX('PRODUCT LIST'!E:E,MATCH(F2,'PRODUCT LIST'!C:C,0)) -> 80X35X180
A5: PACKING SIZE | B5: =INDEX('PRODUCT LIST'!G:G,MATCH(F2,'PRODUCT LIST'!C:C,0)) -> 85X40X185
A6: CBM | B6: 85 | C6: 40 | D6: 185 | E6: =B6*C6*D6/1000000 -> 0.629 | F6: =65/E6 -> 103.33863
A7: L | B7: W | C7: H | D7: QTY | E7: SFT | F7: RATE | G7: TOTAL
A8: 33 | B8: 15 | C8: 1 | D8: 1 | E8: =SUM(A8*B8*C8/144*D8) -> 3.4375 | F8: =INDEX(RATE!B:B,MATCH(A8,RATE!A:A,0)) -> 52 | G8: =SUM(E8*F8) -> 178.75
A9: 72 | B9: 14 | C9: 1 | D9: 2 | E9: =SUM(A9*B9*C9/144*D9) -> 14 | F9: =INDEX(RATE!B:B,MATCH(A9,RATE!A:A,0)) -> 62 | G9: =SUM(E9*F9) -> 868
A10: 31 | B10: 14 | C10: 1 | D10: 2 | E10: =SUM(A10*B10*C10/144*D10) -> 6.0277778 | F10: =INDEX(RATE!B:B,MATCH(A10,RATE!A:A,0)) -> 52 | G10: =SUM(E10*F10) -> 313.44444
A11: 31 | B11: 71 | C11: 0.5 | D11: 1 | E11: =SUM(A11*B11*C11/144*D11) -> 7.6423611 | F11: =INDEX(RATE!B:B,MATCH(A11,RATE!A:A,0)) -> 52 | G11: =SUM(E11*F11) -> 397.40278
A12: 71 | B12: 3 | C12: 1 | D12: 4 | E12: =SUM(A12*B12*C12/144*D12) -> 5.9166667 | F12: =INDEX(RATE!B:B,MATCH(A12,RATE!A:A,0)) -> 62 | G12: =SUM(E12*F12) -> 366.83333
A13: 6 | B13: 3 | C13: 3 | D13: 4 | E13: =SUM(A13*B13*C13/144*D13) -> 1.5 | F13: =INDEX(RATE!B:B,MATCH(A13,RATE!A:A,0)) -> 42 | G13: =SUM(E13*F13) -> 63
A14: 31 | B14: 3 | C14: 1 | D14: 2 | E14: =SUM(A14*B14*C14/144*D14) -> 1.2916667 | F14: =INDEX(RATE!B:B,MATCH(A14,RATE!A:A,0)) -> 52 | G14: =SUM(E14*F14) -> 67.166667
A15: TOTAL WOOD | E15: =SUM(E8:E14) -> 39.815972 | G15: =SUM(G8:G14) -> 2254.5972
A16: WASTAGE 20% | E16: =+E15*0.2 -> 7.9631944 | G16: =+G15*0.2 -> 450.91944
A17: TOTAL WOOD CONSUMP. | E17: =SUM(E15:E16) -> 47.779167 | G17: =SUM(G15:G16) -> 2705.5167
A18: WAGES | G18: =INDEX('PRODUCT LIST'!L:L,MATCH(F2,'PRODUCT LIST'!C:C,0)) -> 800
A19: KFD 8% | G19: =G17*8% -> 216.44133
A20: TOTAL | G20: =SUM(G17:G19) -> 3721.958
A21: TRAD MARGIN/ 10% | G21: =G20*10% -> 372.1958
A22: TOTAL PURCHASE | G22: =G21+G20 -> 4094.1538
A23: KNOBS/HANDLE | C23: 0 | D23: PC | F23: 35 | G23: =C23*F23 -> 0
A24: TILE | C24: 0 | D24: SQ.FT | F24: 180 | G24: =C24*F24 -> 0
A25: IRON | C25: 0 | D25: KG | F25: 150 | G25: =C25*F25 -> 0
A26: CNC | C26: 0 | D26: MIN | F26: 2 | G26: =C26*F26 -> 0
A27: POLISH P & F | D27: FIX | E27: =E6 -> 0.629 | F27: =65/E27 -> 103.33863 | G27: =350000/F27 -> 3386.9231
A28: TOTAL | G28: =SUM(G22:G27) -> 7481.0769 | H28: =+G28/78 -> 95.911242 | I28: @78
A29: OH 15% | G29: =G28*15% -> 1122.1615
A30: MISC 15% | G30: =G28*15% -> 1122.1615
A31: TOTAL | G31: =SUM(G28:G30) -> 9725.3999 | H31: =+G31/78 -> 124.68461
A32: MARGIN 20% | G32: =G31*0.2 -> 1945.08
A33: TOTAL COSTING | G33: =G31+G32 -> 11670.48 | H33: =+G33/78 -> 149.62154 | I33: @78
A34: PARAMETRIC COSTING | G34: =G20+G23+G24+G25+G26+G27+G29+G32 -> 10176.123 | H34: =+G34/78 -> 130.46311 | I34: @78

Sheet DF20011
D1: DESCRIPTION | F1: ='PRODUCT LIST'!D12 -> TV UNIT 2 DOOR 1 DRAWER
D2: PRODUCT CODE | F2: ='PRODUCT LIST'!C12 -> DF20011
B3: L | C3: W | D3: H | E3: CBM | F3: LOADABILITY
A4: PRODUCT SIZE | B4: =INDEX('PRODUCT LIST'!E:E,MATCH(F2,'PRODUCT LIST'!C:C,0)) -> 140X40X55
A5: PACKING SIZE | B5: =INDEX('PRODUCT LIST'!G:G,MATCH(F2,'PRODUCT LIST'!C:C,0)) -> 145X45X60
A6: CBM | B6: 145 | C6: 45 | D6: 60 | E6: =B6*C6*D6/1000000 -> 0.3915 | F6: =65/E6 -> 166.0281
A7: L | B7: W | C7: H | D7: QTY | E7: SFT | F7: RATE | G7: TOTAL
A8: 57 | B8: 17 | C8: 1 | D8: 1 | E8: =SUM(A8*B8*C8/144*D8) -> 6.7291667 | F8: =INDEX(RATE!B:B,MATCH(A8,RATE!A:A,0)) -> 62 | G8: =SUM(E8*F8) -> 417.20833
A9: 23 | B9: 16 | C9: 1 | D9: 2 | E9: =SUM(A9*B9*C9/144*D9) -> 5.1111111 | F9: =INDEX(RATE!B:B,MATCH(A9,RATE!A:A,0)) -> 42 | G9: =SUM(E9*F9) -> 214.66667
A10: 55 | B10: 16 | C10: 1 | D10: 2 | E10: =SUM(A10*B10*C10/144*D10) -> 12.222222 | F10: =INDEX(RATE!B:B,MATCH(A10,RATE!A:A,0)) -> 62 | G10: =SUM(E10*F10) -> 757.77778
A11: 55 | B11: 22 | C11: 0.5 | D11: 1 | E11: =SUM(A11*B11*C11/144*D11) -> 4.2013889 | F11: =INDEX(RATE!B:B,MATCH(A11,RATE!A:A,0)) -> 62 | G11: =SUM(E11*F11) -> 260.48611
A12: 22 | B12: 3 | C12: 1 | D12: 4 | E12: =SUM(A12*B12*C12/144*D12) -> 1.8333333 | F12: =INDEX(RATE!B:B,MATCH(A12,RATE!A:A,0)) -> 42 | G12: =SUM(E12*F12) -> 77
A13: 6 | B13: 3 | C13: 3 | D13: 4 | E13: =SUM(A13*B13*C13/144*D13) -> 1.5 | F13: =INDEX(RATE!B:B,MATCH(A13,RATE!A:A,0)) -> 42 | G13: =SUM(E13*F13) -> 63
A14: 55 | B14: 3 | C14: 1 | D14: 2 | E14: =SUM(A14*B14*C14/144*D14) -> 2.2916667 | F14: =INDEX(RATE!B:B,MATCH(A14,RATE!A:A,0)) -> 62 | G14: =SUM(E14*F14) -> 142.08333
A15: TOTAL WOOD | E15: =SUM(E8:E14) -> 33.888889 | G15: =SUM(G8:G14) -> 1932.2222
A16: WASTAGE 20% | E16: =+E15*0.2 -> 6.7777778 | G16: =+G15*0.2 -> 386.44444
A17: TOTAL WOOD CONSUMP. | E17: =SUM(E15:E16) -> 40.666667 | G17: =SUM(G15:G16) -> 2318.6667
A18: WAGES | G18: =INDEX('PRODUCT LIST'!L:L,MATCH(F2,'PRODUCT LIST'!C:C,0)) -> 750
A19: KFD 8% | G19: =G17*8% -> 185.49333
A20: TOTAL | G20: =SUM(G17:G19) -> 3254.16
A21: TRAD MARGIN/ 10% | G21: =G20*10% -> 325.416
A22: TOTAL PURCHASE | G22: =G21+G20 -> 3579.576
A23: KNOBS/HANDLE | C23: 3 | D23: PC | F23: 35 | G23: =C23*F23 -> 105
A24: TILE | C24: 0 | D24: SQ.FT | F24: 180 | G24: =C24*F24 -> 0
A25: IRON | C25: 0 | D25: KG | F25: 150 | G25: =C25*F25 -> 0
A26: CNC | C26: 0 | D26: MIN | F26: 2 | G26: =C26*F26 -> 0
A27: POLISH P & F | D27: FIX | E27: =E6 -> 0.3915 | F27: =65/E27 -> 166.0281 | G27: =350000/F27 -> 2108.0769
A28: TOTAL | G28: =SUM(G22:G27) -> 5792.6529 | H28: =+G28/78 -> 74.264781 | I28: @78
A29: OH 15% | G29: =G28*15% -> 868.89794
A30: MISC 15% | G30: =G28*15% -> 868.89794
A31: TOTAL | G31: =SUM(G28:G30) -> 7530.4488 | H31: =+G31/78 -> 96.544215
A32: MARGIN 20% | G32: =G31*0.2 -> 1506.0898
A33: TOTAL COSTING | G33: =G31+G32 -> 9036.5386 | H33: =+G33/78 -> 115.85306 | I33: @78
A34: PARAMETRIC COSTING | G34: =G20+G23+G24+G25+G26+G27+G29+G32 -> 7842.2246 | H34: =+G34/78 -> 100.54134 | I34: @78

Sheet DF20012
D1: DESCRIPTION | F1: ='PRODUCT LIST'!D13 -> NEST OF 2 SIDE TABLES
D2: PRODUCT CODE | F2: ='PRODUCT LIST'!C13 -> DF20012
B3: L | C3: W | D3: H | E3: CBM | F3: LOADABILITY
A4: PRODUCT SIZE | B4: =INDEX('PRODUCT LIST'!E:E,MATCH(F2,'PRODUCT LIST'!C:C,0)) -> 50X50X55
A5: PACKING SIZE | B5: =INDEX('PRODUCT LIST'!G:G,MATCH(F2,'PRODUCT LIST'!C:C,0)) -> 55X55X60
A6: CBM | B6: 55 | C6: 55 | D6: 60 | E6: =B6*C6*D6/1000000 -> 0.1815 | F6: =65/E6 -> 358.12672
A7: L | B7: W | C7: H | D7: QTY | E7: SFT | F7: RATE | G7: TOTAL
A8: 22 | B8: 22 | C8: 1 | D8: 1 | E8: =SUM(A8*B8*C8/144*D8) -> 3.3611111 | F8: =INDEX(RATE!B:B,MATCH(A8,RATE!A:A,0)) -> 42 | G8: =SUM(E8*F8) -> 141.16667
A9: 22 | B9: 3 | C9: 3 | D9: 4 | E9: =SUM(A9*B9*C9/144*D9) -> 5.5 | F9: =INDEX(RATE!B:B,MATCH(A9,RATE!A:A,0)) -> 42 | G9: =SUM(E9*F9) -> 231
A10: 20 | B10: 4 | C10: 1 | D10: 2 | E10: =SUM(A10*B10*C10/144*D10) -> 1.1111111 | F10: =INDEX(RATE!B:B,MATCH(A10,RATE!A:A,0)) -> 42 | G10: =SUM(E10*F10) -> 46.666667
A11: 20 | B11: 4 | C11: 1 | D11: 2 | E11: =SUM(A11*B11*C11/144*D11) -> 1.1111111 | F11: =INDEX(RATE!B:B,MATCH(A11,RATE!A:A,0)) -> 42 | G11: =SUM(E11*F11) -> 46.666667
A12: TOTAL WOOD | E12: =SUM(E8:E11) -> 11.083333 | G12: =SUM(G8:G11) -> 465.5
A13: WASTAGE 20% | E13: =+E12*0.2 -> 2.2166667 | G13: =+G12*0.2 -> 93.1
A14: TOTAL WOOD CONSUMP. | E14: =SUM(E12:E13) -> 13.3 | G14: =SUM(G12:G13) -> 558.6
A15: WAGES | G15: =INDEX('PRODUCT LIST'!L:L,MATCH(F2,'PRODUCT LIST'!C:C,0)) -> 400
A16: KFD 8% | G16: =G14*8% -> 44.688
A17: TOTAL | G17: =SUM(G14:G16) -> 1003.288
A18: TRAD MARGIN/ 10% | G18: =G17*10% -> 100.3288
A19: TOTAL PURCHASE | G19: =G18+G17 -> 1103.6168
A20: KNOBS/HANDLE | C20: 0 | D20: PC | F20: 35 | G20: =C20*F20 -> 0
A21: TILE | C21: 0 | D21: SQ.FT | F21: 180 | G21: =C21*F21 -> 0
A22: IRON | C22: 0 | D22: KG | F22: 150 | G22: =C22*F22 -> 0
A23: CNC | C23: 0 | D23: MIN | F23: 2 | G23: =C23*F23 -> 0
A24: POLISH P & F | D24: FIX | E24: =E6 -> 0.1815 | F24: =65/E24 -> 358.12672 | G24: =350000/F24 -> 977.30769
A25: TOTAL | G25: =SUM(G19:G24) -> 2080.9245 | H25: =+G25/78 -> 26.678519 | I25: @78
A26: OH 15% | G26: =G25*15% -> 312.13867
A27: MISC 15% | G27: =G25*15% -> 312.13867
A28: TOTAL | G28: =SUM(G25:G27) -> 2705.2018 | H28: =+G28/78 -> 34.682075
A29: MARGIN 20% | G29: =G28*0.2 -> 541.04037
A30: TOTAL COSTING | G30: =G28+G29 -> 3246.2422 | H30: =+G30/78 -> 41.61849 | I30: @78
A31: PARAMETRIC COSTING | G31: =G17+G20+G21+G22+G23+G24+G26+G29 -> 2833.7747 | H31: =+G31/78 -> 36.330445 | I31: @78

Sheet DF20013
D1: DESCRIPTION | F1: ='PRODUCT LIST'!D14 -> BAR CABINET WITH IRON FRAME
D2: PRODUCT CODE | F2: ='PRODUCT LIST'!C14 -> DF20013
B3: L | C3: W | D3: H | E3: CBM | F3: LOADABILITY
A4: PRODUCT SIZE | B4: =INDEX('PRODUCT LIST'!E:E,MATCH(F2,'PRODUCT LIST'!C:C,0)) -> 90X45X110
A5: PACKING SIZE | B5: =INDEX('PRODUCT LIST'!G:G,MATCH(F2,'PRODUCT LIST'!C:C,0)) -> 95X50X115
A6: CBM | B6: 95 | C6: 50 | D6: 115 | E6: =B6*C6*D6/1000000 -> 0.54625 | F6: =65/E6 -> 118.99314
A7: L | B7: W | C7: H | D7: QTY | E7: SFT | F7: RATE | G7: TOTAL
A8: 37 | B8: 19 | C8: 1 | D8: 1 | E8: =SUM(A8*B8*C8/144*D8) -> 4.8819444 | F8: =INDEX(RATE!B:B,MATCH(A8,RATE!A:A,0)) -> 52 | G8: =SUM(E8*F8) -> 253.86111
A9: 44 | B9: 18 | C9: 1 | D9: 2 | E9: =SUM(A9*B9*C9/144*D9) -> 11 | F9: =INDEX(RATE!B:B,MATCH(A9,RATE!A:A,0)) -> 52 | G9: =SUM(E9*F9) -> 572
A10: 35 | B10: 18 | C10: 1 | D10: 2 | E10: =SUM(A10*B10*C10/144*D10) -> 8.75 | F10: =INDEX(RATE!B:B,MATCH(A10,RATE!A:A,0)) -> 52 | G10: =SUM(E10*F10) -> 455
A11: 35 | B11: 43 | C11: 0.5 | D11: 1 | E11: =SUM(A11*B11*C11/144*D11) -> 5.2256944 | F11: =INDEX(RATE!B:B,MATCH(A11,RATE!A:A,0)) -> 52 | G11: =SUM(E11*F11) -> 271.73611
A12: 43 | B12: 3 | C12: 1 | D12: 4 | E12: =SUM(A12*B12*C12/144*D12) -> 3.5833333 | F12: =INDEX(RATE!B:B,MATCH(A12,RATE!A:A,0)) -> 52 | G12: =SUM(E12*F12) -> 186.33333
A13: 6 | B13: 3 | C13: 3 | D13: 4 | E13: =SUM(A13*B13*C13/144*D13) -> 1.5 | F13: =INDEX(RATE!B:B,MATCH(A13,RATE!A:A,0)) -> 42 | G13: =SUM(E13*F13) -> 63
A14: 35 | B14: 3 | C14: 1 | D14: 2 | E14: =SUM(A14*B14*C14/144*D14) -> 1.4583333 | F14: =INDEX(RATE!B:B,MATCH(A14,RATE!A:A,0)) -> 52 | G14: =SUM(E14*F14) -> 75.833333
A15: TOTAL WOOD | E15: =SUM(E8:E14) -> 36.399306 | G15: =SUM(G8:G14) -> 1877.7639
A16: WASTAGE 20% | E16: =+E15*0.2 -> 7.2798611 | G16: =+G15*0.2 -> 375.55278
A17: TOTAL WOOD CONSUMP. | E17: =SUM(E15:E16) -> 43.679167 | G17: =SUM(G15:G16) -> 2253.3167
A18: WAGES | G18: =INDEX('PRODUCT LIST'!L:L,MATCH(F2,'PRODUCT LIST'!C:C,0)) -> 1050
A19: KFD 8% | G19: =G17*8% -> 180.26533
A20: TOTAL | G20: =SUM(G17:G19) -> 3483.582
A21: TRAD MARGIN/ 10% | G21: =G20*10% -> 348.3582
A22: TOTAL PURCHASE | G22: =G21+G20 -> 3831.9402
A23: KNOBS/HANDLE | C23: 2 | D23: PC | F23: 35 | G23: =C23*F23 -> 70
A24: TILE | C24: 0 | D24: SQ.FT | F24: 180 | G24: =C24*F24 -> 0
A25: IRON | C25: 6 | D25: KG | F25: 150 | G25: =C25*F25 -> 900
A26: CNC | C26: 0 | D26: MIN | F26: 2 | G26: =C26*F26 -> 0
A27: POLISH P & F | D27: FIX | E27: =E6 -> 0.54625 | F27: =65/E27 -> 118.99314 | G27: =350000/F27 -> 2941.3462
A28: TOTAL | G28: =SUM(G22:G27) -> 7743.2864 | H28: =+G28/78 -> 99.272902 | I28: @78
A29: OH 15% | G29: =G28*15% -> 1161.493
A30: MISC 15% | G30: =G28*15% -> 1161.493
A31: TOTAL | G31: =SUM(G28:G30) -> 10066.272 | H31: =+G31/78 -> 129.05477
A32: MARGIN 20% | G32: =G31*0.2 -> 2013.2545
A33: TOTAL COSTING | G33: =G31+G32 -> 12079.527 | H33: =+G33/78 -> 154.86573 | I33: @78
A34: PARAMETRIC COSTING | G34: =G20+G23+G24+G25+G26+G27+G29+G32 -> 10569.676 | H34: =+G34/78 -> 135.50866 | I34: @78

Sheet DF20014
D1: DESCRIPTION | F1: ='PRODUCT LIST'!D15 -> CANE DOOR CABINET
D2: PRODUCT CODE | F2: ='PRODUCT LIST'!C15 -> DF20014
B3: L | C3: W | D3: H | E3: CBM | F3: LOADABILITY
A4: PRODUCT SIZE | B4: =INDEX('PRODUCT LIST'!E:E,MATCH(F2,'PRODUCT LIST'!C:C,0)) -> 80X40X120
A5: PACKING SIZE | B5: =INDEX('PRODUCT LIST'!G:G,MATCH(F2,'PRODUCT LIST'!C:C,0)) -> 85X45X125
A6: CBM | B6: 85 | C6: 45 | D6: 125 | E6: =B6*C6*D6/1000000 -> 0.478125 | F6: =65/E6 -> 135.94771
A7: L | B7: W | C7: H | D7: QTY | E7: SFT | F7: RATE | G7: TOTAL
A8: 33 | B8: 17 | C8: 1 | D8: 1 | E8: =SUM(A8*B8*C8/144*D8) -> 3.8958333 | F8: =INDEX(RATE!B:B,MATCH(A8,RATE!A:A,0)) -> 52 | G8: =SUM(E8*F8) -> 202.58333
A9: 48 | B9: 16 | C9: 1 | D9: 2 | E9: =SUM(A9*B9*C9/144*D9) -> 10.666667 | F9: =INDEX(RATE!B:B,MATCH(A9,RATE!A:A,0)) -> 52 | G9: =SUM(E9*F9) -> 554.66667
A10: 31 | B10: 16 | C10: 1 | D10: 2 | E10: =SUM(A10*B10*C10/144*D10) -> 6.8888889 | F10: =INDEX(RATE!B:B,MATCH(A10,RATE!A:A,0)) -> 52 | G10: =SUM(E10*F10) -> 358.22222
A11: 31 | B11: 47 | C11: 0.5 | D11: 1 | E11: =SUM(A11*B11*C11/144*D11) -> 5.0590278 | F11: =INDEX(RATE!B:B,MATCH(A11,RATE!A:A,0)) -> 52 | G11: =SUM(E11*F11) -> 263.06944
A12: 47 | B12: 3 | C12: 1 | D12: 4 | E12: =SUM(A12*B12*C12/144*D12) -> 3.9166667 | F12: =INDEX(RATE!B:B,MATCH(A12,RATE!A:A,0)) -> 52 | G12: =SUM(E12*F12) -> 203.66667
A13: 6 | B13: 3 | C13: 3 | D13: 4 | E13: =SUM(A13*B13*C13/144*D13) -> 1.5 | F13: =INDEX(RATE!B:B,MATCH(A13,RATE!A:A,0)) -> 42 | G13: =SUM(E13*F13) -> 63
A14: 31 | B14: 3 | C14: 1 | D14: 2 | E14: =SUM(A14*B14*C14/144*D14) -> 1.2916667 | F14: =INDEX(RATE!B:B,MATCH(A14,RATE!A:A,0)) -> 52 | G14: =SUM(E14*F14) -> 67.166667
A15: TOTAL WOOD | E15: =SUM(E8:E14) -> 33.21875 | G15: =SUM(G8:G14) -> 1712.375
A16: WASTAGE 20% | E16: =+E15*0.2 -> 6.64375 | G16: =+G15*0.2 -> 342.475
A17: TOTAL WOOD CONSUMP. | E17: =SUM(E15:E16) -> 39.8625 | G17: =SUM(G15:G16) -> 2054.85
A18: WAGES | G18: =INDEX('PRODUCT LIST'!L:L,MATCH(F2,'PRODUCT LIST'!C:C,0)) -> 950
A19: KFD 8% | G19: =G17*8% -> 164.388
A20: TOTAL | G20: =SUM(G17:G19) -> 3169.238
A21: TRAD MARGIN/ 10% | G21: =G20*10% -> 316.9238
A22: TOTAL PURCHASE | G22: =G21+G20 -> 3486.1618
A23: KNOBS/HANDLE | C23: 2 | D23: PC | F23: 35 | G23: =C23*F23 -> 70
A24: TILE | C24: 0 | D24: SQ.FT | F24: 180 | G24: =C24*F24 -> 0
A25: IRON | C25: 0 | D25: KG | F25: 150 | G25: =C25*F25 -> 0
A26: CNC | C26: 0 | D26: MIN | F26: 2 | G26: =C26*F26 -> 0
A27: POLISH P & F | D27: FIX | E27: =E6 -> 0.478125 | F27: =65/E27 -> 135.94771 | G27: =350000/F27 -> 2574.5192
A28: TOTAL | G28: =SUM(G22:G27) -> 6130.681 | H28: =+G28/78 -> 78.598475 | I28: @78
A29: OH 15% | G29: =G28*15% -> 919.60215
A30: MISC 15% | G30: =G28*15% -> 919.60215
A31: TOTAL | G31: =SUM(G28:G30) -> 7969.8853 | H31: =+G31/78 -> 102.17802
A32: MARGIN 20% | G32: =G31*0.2 -> 1593.9771
A33: TOTAL COSTING | G33: =G31+G32 -> 9563.8624 | H33: =+G33/78 -> 122.61362 | I33: @78
A34: PARAMETRIC COSTING | G34: =G20+G23+G24+G25+G26+G27+G29+G32 -> 8327.3365 | H34: =+G34/78 -> 106.76072 | I34: @78

Sheet DF20015
D1: DESCRIPTION | F1: ='PRODUCT LIST'!D16 -> FLUTED NIGHT STAND
D2: PRODUCT CODE | F2: ='PRODUCT LIST'!C16 -> DF20015
B3: L | C3: W | D3: H | E3: CBM | F3: LOADABILITY
A4: PRODUCT SIZE | B4: =INDEX('PRODUCT LIST'!E:E,MATCH(F2,'PRODUCT LIST'!C:C,0)) -> 45X40X60
A5: PACKING SIZE | B5: =INDEX('PRODUCT LIST'!G:G,MATCH(F2,'PRODUCT LIST'!C:C,0)) -> 50X45X65
A6: CBM | B6: 50 | C6: 45 | D6: 65 | E6: =B6*C6*D6/1000000 -> 0.14625 | F6: =65/E6 -> 444.44444
A7: L | B7: W | C7: H | D7: QTY | E7: SFT | F7: RATE | G7: TOTAL
A8: 20 | B8: 17 | C8: 1 | D8: 1 | E8: =SUM(A8*B8*C8/144*D8) -> 2.3611111 | F8: =INDEX(RATE!B:B,MATCH(A8,RATE!A:A,0)) -> 42 | G8: =SUM(E8*F8) -> 99.166667
A9: 25 | B9: 16 | C9: 1 | D9: 2 | E9: =SUM(A9*B9*C9/144*D9) -> 5.5555556 | F9: =INDEX(RATE!B:B,MATCH(A9,RATE!A:A,0)) -> 52 | G9: =SUM(E9*F9) -> 288.88889
A10: 18 | B10: 16 | C10: 1 | D10: 2 | E10: =SUM(A10*B10*C10/144*D10) -> 4 | F10: =INDEX(RATE!B:B,MATCH(A10,RATE!A:A,0)) -> 42 | G10: =SUM(E10*F10) -> 168
A11: 18 | B11: 24 | C11: 0.5 | D11: 1 | E11: =SUM(A11*B11*C11/144*D11) -> 1.5 | F11: =INDEX(RATE!B:B,MATCH(A11,RATE!A:A,0)) -> 42 | G11: =SUM(E11*F11) -> 63
A12: 24 | B12: 3 | C12: 1 | D12: 4 | E12: =SUM(A12*B12*C12/144*D12) -> 2 | F12: =INDEX(RATE!B:B,MATCH(A12,RATE!A:A,0)) -> 42 | G12: =SUM(E12*F12) -> 84
A13: 6 | B13: 3 | C13: 3 | D13: 4 | E13: =SUM(A13*B13*C13/144*D13) -> 1.5 | F13: =INDEX(RATE!B:B,MATCH(A13,RATE!A:A,0)) -> 42 | G13: =SUM(E13*F13) -> 63
A14: 18 | B14: 3 | C14: 1 | D14: 2 | E14: =SUM(A14*B14*C14/144*D14) -> 0.75 | F14: =INDEX(RATE!B:B,MATCH(A14,RATE!A:A,0)) -> 42 | G14: =SUM(E14*F14) -> 31.5
A15: TOTAL WOOD | E15: =SUM(E8:E14) -> 17.666667 | G15: =SUM(G8:G14) -> 797.55556
A16: WASTAGE 20% | E16: =+E15*0.2 -> 3.5333333 | G16: =+G15*0.2 -> 159.51111
A17: TOTAL WOOD CONSUMP. | E17: =SUM(E15:E16) -> 21.2 | G17: =SUM(G15:G16) -> 957.06667
A18: WAGES | G18: =INDEX('PRODUCT LIST'!L:L,MATCH(F2,'PRODUCT LIST'!C:C,0)) -> 380
A19: KFD 8% | G19: =G17*8% -> 76.565333
A20: TOTAL | G20: =SUM(G17:G19) -> 1413.632
A21: TRAD MARGIN/ 10% | G21: =G20*10% -> 141.3632
A22: TOTAL PURCHASE | G22: =G21+G20 -> 1554.9952
A23: KNOBS/HANDLE | C23: 1 | D23: PC | F23: 35 | G23: =C23*F23 -> 35
A24: TILE | C24: 0 | D24: SQ.FT | F24: 180 | G24: =C24*F24 -> 0
A25: IRON | C25: 0 | D25: KG | F25: 150 | G25: =C25*F25 -> 0
A26: CNC | C26: 30 | D26: MIN | F26: 2 | G26: =C26*F26 -> 60
A27: POLISH P & F | D27: FIX | E27: =E6 -> 0.14625 | F27: =65/E27 -> 444.44444 | G27: =350000/F27 -> 787.5
A28: TOTAL | G28: =SUM(G22:G27) -> 2437.4952 | H28: =+G28/78 -> 31.249938 | I28: @78
A29: OH 15% | G29: =G28*15% -> 365.62428
A30: MISC 15% | G30: =G28*15% -> 365.62428
A31: TOTAL | G31: =SUM(G28:G30) -> 3168.7438 | H31: =+G31/78 -> 40.62492
A32: MARGIN 20% | G32: =G31*0.2 -> 633.74875
A33: TOTAL COSTING | G33: =G31+G32 -> 3802.4925 | H33: =+G33/78 -> 48.749904 | I33: @78
A34: PARAMETRIC COSTING | G34: =G20+G23+G24+G25+G26+G27+G29+G32 -> 3295.505 | H34: =+G34/78 -> 42.250065 | I34: @78

Sheet DF20016
D1: DESCRIPTION | F1: ='PRODUCT LIST'!D17 -> MIRROR WITH CARVED FRAME
D2: PRODUCT CODE | F2: ='PRODUCT LIST'!C17 -> DF20016
B3: L | C3: W | D3: H | E3: CBM | F3: LOADABILITY
A4: PRODUCT SIZE | B4: =INDEX('PRODUCT LIST'!E:E,MATCH(F2,'PRODUCT LIST'!C:C,0)) -> 70X4X100
A5: PACKING SIZE | B5: =INDEX('PRODUCT LIST'!G:G,MATCH(F2,'PRODUCT LIST'!C:C,0)) -> 75X9X105
A6: CBM | B6: 75 | C6: 9 | D6: 105 | E6: =B6*C6*D6/1000000 -> 0.070875 | F6: =65/E6 -> 917.10758
A7: L | B7: W | C7: H | D7: QTY | E7: SFT | F7: RATE | G7: TOTAL
A8: 29 | B8: 4 | C8: 1 | D8: 2 | E8: =SUM(A8*B8*C8/144*D8) -> 1.6111111 | F8: =INDEX(RATE!B:B,MATCH(A8,RATE!A:A,0)) -> 52 | G8: =SUM(E8*F8) -> 83.777778
A9: 40 | B9: 4 | C9: 1 | D9: 2 | E9: =SUM(A9*B9*C9/144*D9) -> 2.2222222 | F9: =INDEX(RATE!B:B,MATCH(A9,RATE!A:A,0)) -> 52 | G9: =SUM(E9*F9) -> 115.55556
A10: TOTAL WOOD | E10: =SUM(E8:E9) -> 3.8333333 | G10: =SUM(G8:G9) -> 199.33333
A11: WASTAGE 20% | E11: =+E10*0.2 -> 0.76666667 | G11: =+G10*0.2 -> 39.866667
A12: TOTAL WOOD CONSUMP. | E12: =SUM(E10:E11) -> 4.6 | G12: =SUM(G10:G11) -> 239.2
A13: WAGES | G13: =INDEX('PRODUCT LIST'!L:L,MATCH(F2,'PRODUCT LIST'!C:C,0)) -> 350
A14: KFD 8% | G14: =G12*8% -> 19.136
A15: TOTAL | G15: =SUM(G12:G14) -> 608.336
A16: TRAD MARGIN/ 10% | G16: =G15*10% -> 60.8336
A17: TOTAL PURCHASE | G17: =G16+G15 -> 669.1696
A18: KNOBS/HANDLE | C18: 0 | D18: PC | F18: 35 | G18: =C18*F18 -> 0
A19: TILE | C19: 4 | D19: SQ.FT | F19: 180 | G19: =C19*F19 -> 720
A20: IRON | C20: 0 | D20: KG | F20: 150 | G20: =C20*F20 -> 0
A21: CNC | C21: 45 | D21: MIN | F21: 2 | G21: =C21*F21 -> 90
A22: POLISH P & F | D22: FIX | E22: =E6 -> 0.070875 | F22: =65/E22 -> 917.10758 | G22: =350000/F22 -> 381.63462
A23: TOTAL | G23: =SUM(G17:G22) -> 1860.8042 | H23: =+G23/78 -> 23.856464 | I23: @78
A24: OH 15% | G24: =G23*15% -> 279.12063
A25: MISC 15% | G25: =G23*15% -> 279.12063
A26: TOTAL | G26: =SUM(G23:G25) -> 2419.0455 | H26: =+G26/78 -> 31.013404
A27: MARGIN 20% | G27: =G26*0.2 -> 483.8091
A28: TOTAL COSTING | G28: =G26+G27 -> 2902.8546 | H28: =+G28/78 -> 37.216084 | I28: @78
A29: PARAMETRIC COSTING | G29: =G15+G18+G19+G20+G21+G22+G24+G27 -> 2562.9003 | H29: =+G29/78 -> 32.857697 | I29: @78

Sheet DF20017
D1: DESCRIPTION | F1: ='PRODUCT LIST'!D18 -> KIDS STUDY DESK
D2: PRODUCT CODE | F2: ='PRODUCT LIST'!C18 -> DF20017
B3: L | C3: W | D3: H | E3: CBM | F3: LOADABILITY
A4: PRODUCT SIZE | B4: =INDEX('PRODUCT LIST'!E:E,MATCH(F2,'PRODUCT LIST'!C:C,0)) -> 100X50X75
A5: PACKING SIZE | B5: =INDEX('PRODUCT LIST'!G:G,MATCH(F2,'PRODUCT LIST'!C:C,0)) -> 105X55X80
A6: CBM | B6: 105 | C6: 55 | D6: 80 | E6: =B6*C6*D6/1000000 -> 0.462 | F6: =65/E6 -> 140.69264
A7: L | B7: W | C7: H | D7: QTY | E7: SFT | F7: RATE | G7: TOTAL
A8: 41 | B8: 22 | C8: 1 | D8: 1 | E8: =SUM(A8*B8*C8/144*D8) -> 6.2638889 | F8: =INDEX(RATE!B:B,MATCH(A8,RATE!A:A,0)) -> 52 | G8: =SUM(E8*F8) -> 325.72222
A9: 30 | B9: 3 | C9: 3 | D9: 4 | E9: =SUM(A9*B9*C9/144*D9) -> 7.5 | F9: =INDEX(RATE!B:B,MATCH(A9,RATE!A:A,0)) -> 52 | G9: =SUM(E9*F9) -> 390
A10: 39 | B10: 4 | C10: 1 | D10: 2 | E10: =SUM(A10*B10*C10/144*D10) -> 2.1666667 | F10: =INDEX(RATE!B:B,MATCH(A10,RATE!A:A,0)) -> 52 | G10: =SUM(E10*F10) -> 112.66667
A11: 20 | B11: 4 | C11: 1 | D11: 2 | E11: =SUM(A11*B11*C11/144*D11) -> 1.1111111 | F11: =INDEX(RATE!B:B,MATCH(A11,RATE!A:A,0)) -> 42 | G11: =SUM(E11*F11) -> 46.666667
A12: TOTAL WOOD | E12: =SUM(E8:E11) -> 17.041667 | G12: =SUM(G8:G11) -> 875.05556
A13: WASTAGE 20% | E13: =+E12*0.2 -> 3.4083333 | G13: =+G12*0.2 -> 175.01111
A14: TOTAL WOOD CONSUMP. | E14: =SUM(E12:E13) -> 20.45 | G14: =SUM(G12:G13) -> 1050.0667
A15: WAGES | G15: =INDEX('PRODUCT LIST'!L:L,MATCH(F2,'PRODUCT LIST'!C:C,0)) -> 600
A16: KFD 8% | G16: =G14*8% -> 84.005333
A17: TOTAL | G17: =SUM(G14:G16) -> 1734.072
A18: TRAD MARGIN/ 10% | G18: =G17*10% -> 173.4072
A19: TOTAL PURCHASE | G19: =G18+G17 -> 1907.4792
A20: KNOBS/HANDLE | C20: 1 | D20: PC | F20: 35 | G20: =C20*F20 -> 35
A21: TILE | C21: 0 | D21: SQ.FT | F21: 180 | G21: =C21*F21 -> 0
A22: IRON | C22: 0 | D22: KG | F22: 150 | G22: =C22*F22 -> 0
A23: CNC | C23: 0 | D23: MIN | F23: 2 | G23: =C23*F23 -> 0
A24: POLISH P & F | D24: FIX | E24: =E6 -> 0.462 | F24: =65/E24 -> 140.69264 | G24: =350000/F24 -> 2487.6923
A25: TOTAL | G25: =SUM(G19:G24) -> 4430.1715 | H25: =+G25/78 -> 56.797071 | I25: @78
A26: OH 15% | G26: =G25*15% -> 664.52573
A27: MISC 15% | G27: =G25*15% -> 664.52573
A28: TOTAL | G28: =SUM(G25:G27) -> 5759.223 | H28: =+G28/78 -> 73.836192
A29: MARGIN 20% | G29: =G28*0.2 -> 1151.8446
A30: TOTAL COSTING | G30: =G28+G29 -> 6911.0676 | H30: =+G30/78 -> 88.60343 | I30: @78
A31: PARAMETRIC COSTING | G31: =G17+G20+G21+G22+G23+G24+G26+G29 -> 6073.1346 | H31: =+G31/78 -> 77.8607 | I31: @78

Sheet DF20018
D1: DESCRIPTION | F1: ='PRODUCT LIST'!D19 -> DRESSING TABLE WITH MIRROR
D2: PRODUCT CODE | F2: ='PRODUCT LIST'!C19 -> DF20018
B3: L | C3: W | D3: H | E3: CBM | F3: LOADABILITY
A4: PRODUCT SIZE | B4: =INDEX('PRODUCT LIST'!E:E,MATCH(F2,'PRODUCT LIST'!C:C,0)) -> 110X40X150
A5: PACKING SIZE | B5: =INDEX('PRODUCT LIST'!G:G,MATCH(F2,'PRODUCT LIST'!C:C,0)) -> 115X45X155
A6: CBM | B6: 115 | C6: 45 | D6: 155 | E6: =B6*C6*D6/1000000 -> 0.802125 | F6: =65/E6 -> 81.034751
A7: L | B7: W | C7: H | D7: QTY | E7: SFT | F7: RATE | G7: TOTAL
A8: 45 | B8: 17 | C8: 1 | D8: 1 | E8: =SUM(A8*B8*C8/144*D8) -> 5.3125 | F8: =INDEX(RATE!B:B,MATCH(A8,RATE!A:A,0)) -> 52 | G8: =SUM(E8*F8) -> 276.25
A9: 60 | B9: 16 | C9: 1 | D9: 2 | E9: =SUM(A9*B9*C9/144*D9) -> 13.333333 | F9: =INDEX(RATE!B:B,MATCH(A9,RATE!A:A,0)) -> 62 | G9: =SUM(E9*F9) -> 826.66667
A10: 43 | B10: 16 | C10: 1 | D10: 2 | E10: =SUM(A10*B10*C10/144*D10) -> 9.5555556 | F10: =INDEX(RATE!B:B,MATCH(A10,RATE!A:A,0)) -> 52 | G10: =SUM(E10*F10) -> 496.88889
A11: 43 | B11: 59 | C11: 0.5 | D11: 1 | E11: =SUM(A11*B11*C11/144*D11) -> 8.8090278 | F11: =INDEX(RATE!B:B,MATCH(A11,RATE!A:A,0)) -> 52 | G11: =SUM(E11*F11) -> 458.06944
A12: 59 | B12: 3 | C12: 1 | D12: 4 | E12: =SUM(A12*B12*C12/144*D12) -> 4.9166667 | F12: =INDEX(RATE!B:B,MATCH(A12,RATE!A:A,0)) -> 62 | G12: =SUM(E12*F12) -> 304.83333
A13: 6 | B13: 3 | C13: 3 | D13: 4 | E13: =SUM(A13*B13*C13/144*D13) -> 1.5 | F13: =INDEX(RATE!B:B,MATCH(A13,RATE!A:A,0)) -> 42 | G13: =SUM(E13*F13) -> 63
A14: 43 | B14: 3 | C14: 1 | D14: 2 | E14: =SUM(A14*B14*C14/144*D14) -> 1.7916667 | F14: =INDEX(RATE!B:B,MATCH(A14,RATE!A:A,0)) -> 52 | G14: =SUM(E14*F14) -> 93.166667
A15: TOTAL WOOD | E15: =SUM(E8:E14) -> 45.21875 | G15: =SUM(G8:G14) -> 2518.875
A16: WASTAGE 20% | E16: =+E15*0.2 -> 9.04375 | G16: =+G15*0.2 -> 503.775
A17: TOTAL WOOD CONSUMP. | E17: =SUM(E15:E16) -> 54.2625 | G17: =SUM(G15:G16) -> 3022.65
A18: WAGES | G18: =INDEX('PRODUCT LIST'!L:L,MATCH(F2,'PRODUCT LIST'!C:C,0)) -> 1000
A19: KFD 8% | G19: =G17*8% -> 241.812
A20: TOTAL | G20: =SUM(G17:G19) -> 4264.462
A21: TRAD MARGIN/ 10% | G21: =G20*10% -> 426.4462
A22: TOTAL PURCHASE | G22: =G21+G20 -> 4690.9082
A23: KNOBS/HANDLE | C23: 3 | D23: PC | F23: 35 | G23: =C23*F23 -> 105
A24: TILE | C24: 3 | D24: SQ.FT | F24: 180 | G24: =C24*F24 -> 540
A25: IRON | C25: 0 | D25: KG | F25: 150 | G25: =C25*F25 -> 0
A26: CNC | C26: 0 | D26: MIN | F26: 2 | G26: =C26*F26 -> 0
A27: POLISH P & F | D27: FIX | E27: =E6 -> 0.802125 | F27: =65/E27 -> 81.034751 | G27: =350000/F27 -> 4319.1346
A28: TOTAL | G28: =SUM(G22:G27) -> 9655.0428 | H28: =+G28/78 -> 123.7826 | I28: @78
A29: OH 15% | G29: =G28*15% -> 1448.2564
A30: MISC 15% | G30: =G28*15% -> 1448.2564
A31: TOTAL | G31: =SUM(G28:G30) -> 12551.556 | H31: =+G31/78 -> 160.91738
A32: MARGIN 20% | G32: =G31*0.2 -> 2510.3111
A33: TOTAL COSTING | G33: =G31+G32 -> 15061.867 | H33: =+G33/78 -> 193.10086 | I33: @78
A34: PARAMETRIC COSTING | G34: =G20+G23+G24+G25+G26+G27+G29+G32 -> 13187.164 | H34: =+G34/78 -> 169.06621 | I34: @78

Sheet DF20019
D1: DESCRIPTION | F1: ='PRODUCT LIST'!D20 -> COAT RACK 6 HOOKS
D2: PRODUCT CODE | F2: ='PRODUCT LIST'!C20 -> DF20019
B3: L | C3: W | D3: H | E3: CBM | F3: LOADABILITY
A4: PRODUCT SIZE | B4: =INDEX('PRODUCT LIST'!E:E,MATCH(F2,'PRODUCT LIST'!C:C,0)) -> 100X8X30
A5: PACKING SIZE | B5: =INDEX('PRODUCT LIST'!G:G,MATCH(F2,'PRODUCT LIST'!C:C,0)) -> 105X13X35
A6: CBM | B6: 105 | C6: 13 | D6: 35 | E6: =B6*C6*D6/1000000 -> 0.047775 | F6: =65/E6 -> 1360.5442
A7: L | B7: W | C7: H | D7: QTY | E7: SFT | F7: RATE | G7: TOTAL
A8: 40 | B8: 4 | C8: 1 | D8: 2 | E8: =SUM(A8*B8*C8/144*D8) -> 2.2222222 | F8: =INDEX(RATE!B:B,MATCH(A8,RATE!A:A,0)) -> 52 | G8: =SUM(E8*F8) -> 115.55556
A9: 13 | B9: 4 | C9: 1 | D9: 2 | E9: =SUM(A9*B9*C9/144*D9) -> 0.72222222 | F9: =INDEX(RATE!B:B,MATCH(A9,RATE!A:A,0)) -> 42 | G9: =SUM(E9*F9) -> 30.333333
A10: TOTAL WOOD | E10: =SUM(E8:E9) -> 2.9444444 | G10: =SUM(G8:G9) -> 145.88889
A11: WASTAGE 20% | E11: =+E10*0.2 -> 0.58888889 | G11: =+G10*0.2 -> 29.177778
A12: TOTAL WOOD CONSUMP. | E12: =SUM(E10:E11) -> 3.5333333 | G12: =SUM(G10:G11) -> 175.06667
A13: WAGES | G13: =INDEX('PRODUCT LIST'!L:L,MATCH(F2,'PRODUCT LIST'!C:C,0)) -> 150
A14: KFD 8% | G14: =G12*8% -> 14.005333
A15: TOTAL | G15: =SUM(G12:G14) -> 339.072
A16: TRAD MARGIN/ 10% | G16: =G15*10% -> 33.9072
A17: TOTAL PURCHASE | G17: =G16+G15 -> 372.9792
A18: KNOBS/HANDLE | C18: 0 | D18: PC | F18: 35 | G18: =C18*F18 -> 0
A19: TILE | C19: 0 | D19: SQ.FT | F19: 180 | G19: =C19*F19 -> 0
A20: IRON | C20: 1 | D20: KG | F20: 150 | G20: =C20*F20 -> 150
A21: CNC | C21: 0 | D21: MIN | F21: 2 | G21: =C21*F21 -> 0
A22: POLISH P & F | D22: FIX | E22: =E6 -> 0.047775 | F22: =65/E22 -> 1360.5442 | G22: =350000/F22 -> 257.25
A23: TOTAL | G23: =SUM(G17:G22) -> 780.2292 | H23: =+G23/78 -> 10.002938 | I23: @78
A24: OH 15% | G24: =G23*15% -> 117.03438
A25: MISC 15% | G25: =G23*15% -> 117.03438
A26: TOTAL | G26: =SUM(G23:G25) -> 1014.298 | H26: =+G26/78 -> 13.00382
A27: MARGIN 20% | G27: =G26*0.2 -> 202.85959
A28: TOTAL COSTING | G28: =G26+G27 -> 1217.1576 | H28: =+G28/78 -> 15.604584 | I28: @78
A29: PARAMETRIC COSTING | G29: =G15+G18+G19+G20+G21+G22+G24+G27 -> 1066.216 | H29: =+G29/78 -> 13.669436 | I29: @78

Sheet DF20020
D1: DESCRIPTION | F1: ='PRODUCT LIST'!D21 -> HERRINGBONE COFFEE TABLE
D2: PRODUCT CODE | F2: ='PRODUCT LIST'!C21 -> DF20020
B3: L | C3: W | D3: H | E3: CBM | F3: LOADABILITY
